Workbook

Sheet Inputs
A1: RETIREMENT PLANNING MODEL — INPUTS
A2: Blue = your inputs (change these) | Black = formulas | Orange rows = RMD years
A3: YOUR DETAILS | D3: WIFE DETAILS
A4: Your Current Age | B4: 56 | D4: Wife Current Age | E4: 51
A5: Retirement Age | B5: 65 | D5: Wife Retirement Age | E5: 65
A6: Life Expectancy | B6: 85 | D6: Wife Salary ($) | E6: 0
A7: State of Residence (abbr) | B7: NJ | D7: Wife 401k Balance ($) | E7: 0
A8: Current Salary ($) | B8: 300000 | D8: Wife 401k Contribution ($/yr) | E8: 0
A9: Trad. 401k Balance ($) | B9: 3000000 | D9: Wife Match Rate (%) | E9: 0
A10: Roth 401k Balance ($) | B10: 500000 | D10: Wife Trad IRA ($) | E10: 50000
A11: Your 401k Contribution ($/yr) | B11: 37500 | D11: Wife Roth IRA ($) | E11: 10000
A12: Company Match Rate (%) | B12: 0.05
A13: Roth IRA — Your ($) | B13: 250000
A14: HSA Balance ($) | B14: 100000
A15: HSA 2025 Contribution ($/yr) | B15: 8000
A16: Brokerage Account ($) | B16: 500000
A18: GROWTH & SOCIAL SECURITY
A19: Investment Growth Rate (%) | B19: 0.08
A20: Inflation Rate (%) | B20: 0.03
A21: SS COLA Rate (%) | B21: 0.025
A22: SS Monthly @ Age 65 ($) | B22: 3330
A23: SS Monthly @ Age 67 ($) | B23: 3972
A24: SS Monthly @ Age 70 ($) | B24: 5200
A25: SS Start Age (65/67/70) | B25: 67
A26: Wife SS Start Age | B26: 65
A28: EXPENSES
A29: Monthly Living Expenses ($) | B29: 7000
A30: Mortgage Monthly ($) | B30: 3000
A31: Property Tax Annual ($) | B31: 15000
A32: Home Insurance Annual ($) | B32: 1500
A33: Medicare Part B / mo ($) | B33: 185
A34: Medicare Inflation Rate (%) | B34: 0.05
A35: Wife Private Ins / mo ($) pre-65 | B35: 800
A36: Home Value ($) | B36: 800000
A37: Annual Gift to Children ($) | B37: 0
A38: Gift Start Age | B38: 70
A40: TAX & CONVERSION STRATEGY
A41: Roth Conv. Target ($/yr) | B41: 201050
A42: Federal Std. Deduction ($) | B42: 30000
A43: SS Taxable Portion (%) | B43: 0.85
...

Sheet Roth Conversion
A1: ROTH CONVERSION PLAN (Ages 65–85)
A2: Age | B2: Trad 401k Start ($) | C2: SS Income ($) | D2: Taxable Pre- Conv ($) | E2: Roth Conv ($) | F2: Total Taxable ($) | G2: Fed Tax ($) | H2: Eff Rate | I2: IRMAA Tier | J2: Trad 401k End ($)
A3: 65 | B3: =Inputs!B9 -> 3000000 | C3: =IF(65>=Inputs!B25,IF(Inputs!B25=65,Inputs!B22*12,IF(Inputs!B25=70,Inputs!B24*12,Inputs!B23*12))*(1+Inputs!B21)^MAX(0,65-Inputs!B25),0) -> 0 | D3: =C3*Inputs!B43 -> 0 | E3: =MAX(0,Inputs!B41-D3-Inputs!B42) -> 171050 | F3: =D3+E3 -> 171050 | G3: =MAX(0,IF(F3<=23200,F3*0.1,IF(F3<=94300,23200*0.1+(F3-23200)*0.12,IF(F3<=201050,23200*0.1+71100*0.12+(F3-94300)*0.22,IF(F3<=383900,23200*0.1+71100*0.12+106750*0.22+(F3-201050)*0.24,23200*0.1+71100*0.12+106750*0.22+182850*0.24+(F3-383900)*0.32))))) -> 27737 | H3: =IFERROR(G3/F3,0) -> 0.16215726 | I3: =IF(F3<=206000,"Tier 0 — $0/yr",IF(F3<=258000,"Tier 1 — $594/yr",IF(F3<=322000,"Tier 2 — $1,494/yr",IF(F3<=386000,"Tier 3 — $2,394/yr",IF(F3<=750000,"Tier 4 — $3,270/yr","Tier 5 — $3,564/yr"))))) -> Tier 0 — $0/yr | J3: =MAX(0,B3-E3) -> 2828950
A4: 66 | B4: =J3 -> 2828950 | C4: =IF(66>=Inputs!B25,IF(Inputs!B25=65,Inputs!B22*12,IF(Inputs!B25=70,Inputs!B24*12,Inputs!B23*12))*(1+Inputs!B21)^MAX(0,66-Inputs!B25),0) -> 0 | D4: =C4*Inputs!B43 -> 0 | E4: =MAX(0,Inputs!B41-D4-Inputs!B42) -> 171050 | F4: =D4+E4 -> 171050 | G4: =MAX(0,IF(F4<=23200,F4*0.1,IF(F4<=94300,23200*0.1+(F4-23200)*0.12,IF(F4<=201050,23200*0.1+71100*0.12+(F4-94300)*0.22,IF(F4<=383900,23200*0.1+71100*0.12+106750*0.22+(F4-201050)*0.24,23200*0.1+71100*0.12+106750*0.22+182850*0.24+(F4-383900)*0.32))))) -> 27737 | H4: =IFERROR(G4/F4,0) -> 0.16215726 | I4: =IF(F4<=206000,"Tier 0 — $0/yr",IF(F4<=258000,"Tier 1 — $594/yr",IF(F4<=322000,"Tier 2 — $1,494/yr",IF(F4<=386000,"Tier 3 — $2,394/yr",IF(F4<=750000,"Tier 4 — $3,270/yr","Tier 5 — $3,564/yr"))))) -> Tier 0 — $0/yr | J4: =MAX(0,B4-E4) -> 2657900
A5: 67 | B5: =J4 -> 2657900 | C5: =IF(67>=Inputs!B25,IF(Inputs!B25=65,Inputs!B22*12,IF(Inputs!B25=70,Inputs!B24*12,Inputs!B23*12))*(1+Inputs!B21)^MAX(0,67-Inputs!B25),0) -> 47664 | D5: =C5*Inputs!B43 -> 40514.4 | E5: =MAX(0,Inputs!B41-D5-Inputs!B42) -> 130535.6 | F5: =D5+E5 -> 171050 | G5: =MAX(0,IF(F5<=23200,F5*0.1,IF(F5<=94300,23200*0.1+(F5-23200)*0.12,IF(F5<=201050,23200*0.1+71100*0.12+(F5-94300)*0.22,IF(F5<=383900,23200*0.1+71100*0.12+106750*0.22+(F5-201050)*0.24,23200*0.1+71100*0.12+106750*0.22+182850*0.24+(F5-383900)*0.32))))) -> 27737 | H5: =IFERROR(G5/F5,0) -> 0.16215726 | I5: =IF(F5<=206000,"Tier 0 — $0/yr",IF(F5<=258000,"Tier 1 — $594/yr",IF(F5<=322000,"Tier 2 — $1,494/yr",IF(F5<=386000,"Tier 3 — $2,394/yr",IF(F5<=750000,"Tier 4 — $3,270/yr","Tier 5 — $3,564/yr"))))) -> Tier 0 — $0/yr | J5: =MAX(0,B5-E5) -> 2527364.4
A6: 68 | B6: =J5 -> 2527364.4 | C6: =IF(68>=Inputs!B25,IF(Inputs!B25=65,Inputs!B22*12,IF(Inputs!B25=70,Inputs!B24*12,Inputs!B23*12))*(1+Inputs!B21)^MAX(0,68-Inputs!B25),0) -> 48855.6 | D6: =C6*Inputs!B43 -> 41527.26 | E6: =MAX(0,Inputs!B41-D6-Inputs!B42) -> 129522.74 | F6: =D6+E6 -> 171050 | G6: =MAX(0,IF(F6<=23200,F6*0.1,IF(F6<=94300,23200*0.1+(F6-23200)*0.12,IF(F6<=201050,23200*0.1+71100*0.12+(F6-94300)*0.22,IF(F6<=383900,23200*0.1+71100*0.12+106750*0.22+(F6-201050)*0.24,23200*0.1+71100*0.12+106750*0.22+182850*0.24+(F6-383900)*0.32))))) -> 27737 | H6: =IFERROR(G6/F6,0) -> 0.16215726 | I6: =IF(F6<=206000,"Tier 0 — $0/yr",IF(F6<=258000,"Tier 1 — $594/yr",IF(F6<=322000,"Tier 2 — $1,494/yr",IF(F6<=386000,"Tier 3 — $2,394/yr",IF(F6<=750000,"Tier 4 — $3,270/yr","Tier 5 — $3,564/yr"))))) -> Tier 0 — $0/yr | J6: =MAX(0,B6-E6) -> 2397841.7
A7: 69 | B7: =J6 -> 2397841.7 | C7: =IF(69>=Inputs!B25,IF(Inputs!B25=65,Inputs!B22*12,IF(Inputs!B25=70,Inputs!B24*12,Inputs!B23*12))*(1+Inputs!B21)^MAX(0,69-Inputs!B25),0) -> 50076.99 | D7: =C7*Inputs!B43 -> 42565.442 | E7: =MAX(0,Inputs!B41-D7-Inputs!B42) -> 128484.56 | F7: =D7+E7 -> 171050 | G7: =MAX(0,IF(F7<=23200,F7*0.1,IF(F7<=94300,23200*0.1+(F7-23200)*0.12,IF(F7<=201050,23200*0.1+71100*0.12+(F7-94300)*0.22,IF(F7<=383900,23200*0.1+71100*0.12+106750*0.22+(F7-201050)*0.24,23200*0.1+71100*0.12+106750*0.22+182850*0.24+(F7-383900)*0.32))))) -> 27737 | H7: =IFERROR(G7/F7,0) -> 0.16215726 | I7: =IF(F7<=206000,"Tier 0 — $0/yr",IF(F7<=258000,"Tier 1 — $594/yr",IF(F7<=322000,"Tier 2 — $1,494/yr",IF(F7<=386000,"Tier 3 — $2,394/yr",IF(F7<=750000,"Tier 4 — $3,270/yr","Tier 5 — $3,564/yr"))))) -> Tier 0 — $0/yr | J7: =MAX(0,B7-E7) -> 2269357.1
A8: 70 | B8: =J7 -> 2269357.1 | C8: =IF(70>=Inputs!B25,IF(Inputs!B25=65,Inputs!B22*12,IF(Inputs!B25=70,Inputs!B24*12,Inputs!B23*12))*(1+Inputs!B21)^MAX(0,70-Inputs!B25),0) -> 51328.915 | D8: =C8*Inputs!B43 -> 43629.578 | E8: =MAX(0,Inputs!B41-D8-Inputs!B42) -> 127420.42 | F8: =D8+E8 -> 171050 | G8: =MAX(0,IF(F8<=23200,F8*0.1,IF(F8<=94300,23200*0.1+(F8-23200)*0.12,IF(F8<=201050,23200*0.1+71100*0.12+(F8-94300)*0.22,IF(F8<=383900,23200*0.1+71100*0.12+106750*0.22+(F8-201050)*0.24,23200*0.1+71100*0.12+106750*0.22+182850*0.24+(F8-383900)*0.32))))) -> 27737 | H8: =IFERROR(G8/F8,0) -> 0.16215726 | I8: =IF(F8<=206000,"Tier 0 — $0/yr",IF(F8<=258000,"Tier 1 — $594/yr",IF(F8<=322000,"Tier 2 — $1,494/yr",IF(F8<=386000,"Tier 3 — $2,394/yr",IF(F8<=750000,"Tier 4 — $3,270/yr","Tier 5 — $3,564/yr"))))) -> Tier 0 — $0/yr | J8: =MAX(0,B8-E8) -> 2141936.7
A9: 71 | B9: =J8 -> 2141936.7 | C9: =IF(71>=Inputs!B25,IF(Inputs!B25=65,Inputs!B22*12,IF(Inputs!B25=70,Inputs!B24*12,Inputs!B23*12))*(1+Inputs!B21)^MAX(0,71-Inputs!B25),0) -> 52612.138 | D9: =C9*Inputs!B43 -> 44720.317 | E9: =MAX(0,Inputs!B41-D9-Inputs!B42) -> 126329.68 | F9: =D9+E9 -> 171050 | G9: =MAX(0,IF(F9<=23200,F9*0.1,IF(F9<=94300,23200*0.1+(F9-23200)*0.12,IF(F9<=201050,23200*0.1+71100*0.12+(F9-94300)*0.22,IF(F9<=383900,23200*0.1+71100*0.12+106750*0.22+(F9-201050)*0.24,23200*0.1+71100*0.12+106750*0.22+182850*0.24+(F9-383900)*0.32))))) -> 27737 | H9: =IFERROR(G9/F9,0) -> 0.16215726 | I9: =IF(F9<=206000,"Tier 0 — $0/yr",IF(F9<=258000,"Tier 1 — $594/yr",IF(F9<=322000,"Tier 2 — $1,494/yr",IF(F9<=386000,"Tier 3 — $2,394/yr",IF(F9<=750000,"Tier 4 — $3,270/yr","Tier 5 — $3,564/yr"))))) -> Tier 0 — $0/yr | J9: =MAX(0,B9-E9) -> 2015607
A10: 72 | B10: =J9 -> 2015607 | C10: =IF(72>=Inputs!B25,IF(Inputs!B25=65,Inputs!B22*12,IF(Inputs!B25=70,Inputs!B24*12,Inputs!B23*12))*(1+Inputs!B21)^MAX(0,72-Inputs!B25),0) -> 53927.441 | D10: =C10*Inputs!B43 -> 45838.325 | E10: =MAX(0,Inputs!B41-D10-Inputs!B42) -> 125211.68 | F10: =D10+E10 -> 171050 | G10: =MAX(0,IF(F10<=23200,F10*0.1,IF(F10<=94300,23200*0.1+(F10-23200)*0.12,IF(F10<=201050,23200*0.1+71100*0.12+(F10-94300)*0.22,IF(F10<=383900,23200*0.1+71100*0.12+106750*0.22+(F10-201050)*0.24,23200*0.1+71100*0.12+106750*0.22+182850*0.24+(F10-383900)*0.32))))) -> 27737 | H10: =IFERROR(G10/F10,0) -> 0.16215726 | I10: =IF(F10<=206000,"Tier 0 — $0/yr",IF(F10<=258000,"Tier 1 — $594/yr",IF(F10<=322000,"Tier 2 — $1,494/yr",IF(F10<=386000,"Tier 3 — $2,394/yr",IF(F10<=750000,"Tier 4 — $3,270/yr","Tier 5 — $3,564/yr"))))) -> Tier 0 — $0/yr | J10: =MAX(0,B10-E10) -> 1890395.3
A11: 73 | B11: =J10 -> 1890395.3 | C11: =IF(73>=Inputs!B25,IF(Inputs!B25=65,Inputs!B22*12,IF(Inputs!B25=70,Inputs!B24*12,Inputs!B23*12))*(1+Inputs!B21)^MAX(0,73-Inputs!B25),0) -> 55275.627 | D11: =C11*Inputs!B43 -> 46984.283 | E11: =MAX(0,Inputs!B41-D11-Inputs!B42) -> 124065.72 | F11: =D11+E11 -> 171050 | G11: =MAX(0,IF(F11<=23200,F11*0.1,IF(F11<=94300,23200*0.1+(F11-23200)*0.12,IF(F11<=201050,23200*0.1+71100*0.12+(F11-94300)*0.22,IF(F11<=383900,23200*0.1+71100*0.12+106750*0.22+(F11-201050)*0.24,23200*0.1+71100*0.12+106750*0.22+182850*0.24+(F11-383900)*0.32))))) -> 27737 | H11: =IFERROR(G11/F11,0) -> 0.16215726 | I11: =IF(F11<=206000,"Tier 0 — $0/yr",IF(F11<=258000,"Tier 1 — $594/yr",IF(F11<=322000,"Tier 2 — $1,494/yr",IF(F11<=386000,"Tier 3 — $2,394/yr",IF(F11<=750000,"Tier 4 — $3,270/yr","Tier 5 — $3,564/yr"))))) -> Tier 0 — $0/yr | J11: =MAX(0,B11-E11) -> 1766329.6
A12: 74 | B12: =J11 -> 1766329.6 | C12: =IF(74>=Inputs!B25,IF(Inputs!B25=65,Inputs!B22*12,IF(Inputs!B25=70,Inputs!B24*12,Inputs!B23*12))*(1+Inputs!B21)^MAX(0,74-Inputs!B25),0) -> 56657.518 | D12: =C12*Inputs!B43 -> 48158.89 | E12: =MAX(0,Inputs!B41-D12-Inputs!B42) -> 122891.11 | F12: =D12+E12 -> 171050 | G12: =MAX(0,IF(F12<=23200,F12*0.1,IF(F12<=94300,23200*0.1+(F12-23200)*0.12,IF(F12<=201050,23200*0.1+71100*0.12+(F12-94300)*0.22,IF(F12<=383900,23200*0.1+71100*0.12+106750*0.22+(F12-201050)*0.24,23200*0.1+71100*0.12+106750*0.22+182850*0.24+(F12-383900)*0.32))))) -> 27737 | H12: =IFERROR(G12/F12,0) -> 0.16215726 | I12: =IF(F12<=206000,"Tier 0 — $0/yr",IF(F12<=258000,"Tier 1 — $594/yr",IF(F12<=322000,"Tier 2 — $1,494/yr",IF(F12<=386000,"Tier 3 — $2,394/yr",IF(F12<=750000,"Tier 4 — $3,270/yr","Tier 5 — $3,564/yr"))))) -> Tier 0 — $0/yr | J12: =MAX(0,B12-E12) -> 1643438.5
A13: 75 | B13: =J12 -> 1643438.5 | C13: =IF(75>=Inputs!B25,IF(Inputs!B25=65,Inputs!B22*12,IF(Inputs!B25=70,Inputs!B24*12,Inputs!B23*12))*(1+Inputs!B21)^MAX(0,75-Inputs!B25),0) -> 58073.956 | D13: =C13*Inputs!B43 -> 49362.862 | E13: =MAX(0,Inputs!B41-D13-Inputs!B42) -> 121687.14 | F13: =D13+E13 -> 171050 | G13: =MAX(0,IF(F13<=23200,F13*0.1,IF(F13<=94300,23200*0.1+(F13-23200)*0.12,IF(F13<=201050,23200*0.1+71100*0.12+(F13-94300)*0.22,IF(F13<=383900,23200*0.1+71100*0.12+106750*0.22+(F13-201050)*0.24,23200*0.1+71100*0.12+106750*0.22+182850*0.24+(F13-383900)*0.32))))) -> 27737 | H13: =IFERROR(G13/F13,0) -> 0.16215726 | I13: =IF(F13<=206000,"Tier 0 — $0/yr",IF(F13<=258000,"Tier 1 — $594/yr",IF(F13<=322000,"Tier 2 — $1,494/yr",IF(F13<=386000,"Tier 3 — $2,394/yr",IF(F13<=750000,"Tier 4 — $3,270/yr","Tier 5 — $3,564/yr"))))) -> Tier 0 — $0/yr | J13: =MAX(0,B13-E13) -> 1521751.4
A14: 76 | B14: =J13 -> 1521751.4 | C14: =IF(76>=Inputs!B25,IF(Inputs!B25=65,Inputs!B22*12,IF(Inputs!B25=70,Inputs!B24*12,Inputs!B23*12))*(1+Inputs!B21)^MAX(0,76-Inputs!B25),0) -> 59525.805 | D14: =C14*Inputs!B43 -> 50596.934 | E14: =MAX(0,Inputs!B41-D14-Inputs!B42) -> 120453.07 | F14: =D14+E14 -> 171050 | G14: =MAX(0,IF(F14<=23200,F14*0.1,IF(F14<=94300,23200*0.1+(F14-23200)*0.12,IF(F14<=201050,23200*0.1+71100*0.12+(F14-94300)*0.22,IF(F14<=383900,23200*0.1+71100*0.12+106750*0.22+(F14-201050)*0.24,23200*0.1+71100*0.12+106750*0.22+182850*0.24+(F14-383900)*0.32))))) -> 27737 | H14: =IFERROR(G14/F14,0) -> 0.16215726 | I14: =IF(F14<=206000,"Tier 0 — $0/yr",IF(F14<=258000,"Tier 1 — $594/yr",IF(F14<=322000,"Tier 2 — $1,494/yr",IF(F14<=386000,"Tier 3 — $2,394/yr",IF(F14<=750000,"Tier 4 — $3,270/yr","Tier 5 — $3,564/yr"))))) -> Tier 0 — $0/yr | J14: =MAX(0,B14-E14) -> 1401298.3
A15: 77 | B15: =J14 -> 1401298.3 | C15: =IF(77>=Inputs!B25,IF(Inputs!B25=65,Inputs!B22*12,IF(Inputs!B25=70,Inputs!B24*12,Inputs!B23*12))*(1+Inputs!B21)^MAX(0,77-Inputs!B25),0) -> 61013.95 | D15: =C15*Inputs!B43 -> 51861.857 | E15: =MAX(0,Inputs!B41-D15-Inputs!B42) -> 119188.14 | F15: =D15+E15 -> 171050 | G15: =MAX(0,IF(F15<=23200,F15*0.1,IF(F15<=94300,23200*0.1+(F15-23200)*0.12,IF(F15<=201050,23200*0.1+71100*0.12+(F15-94300)*0.22,IF(F15<=383900,23200*0.1+71100*0.12+106750*0.22+(F15-201050)*0.24,23200*0.1+71100*0.12+106750*0.22+182850*0.24+(F15-383900)*0.32))))) -> 27737 | H15: =IFERROR(G15/F15,0) -> 0.16215726 | I15: =IF(F15<=206000,"Tier 0 — $0/yr",IF(F15<=258000,"Tier 1 — $594/yr",IF(F15<=322000,"Tier 2 — $1,494/yr",IF(F15<=386000,"Tier 3 — $2,394/yr",IF(F15<=750000,"Tier 4 — $3,270/yr","Tier 5 — $3,564/yr"))))) -> Tier 0 — $0/yr | J15: =MAX(0,B15-E15) -> 1282110.1
A16: 78 | B16: =J15 -> 1282110.1 | C16: =IF(78>=Inputs!B25,IF(Inputs!B25=65,Inputs!B22*12,IF(Inputs!B25=70,Inputs!B24*12,Inputs!B23*12))*(1+Inputs!B21)^MAX(0,78-Inputs!B25),0) -> 62539.298 | D16: =C16*Inputs!B43 -> 53158.404 | E16: =MAX(0,Inputs!B41-D16-Inputs!B42) -> 117891.6 | F16: =D16+E16 -> 171050 | G16: =MAX(0,IF(F16<=23200,F16*0.1,IF(F16<=94300,23200*0.1+(F16-23200)*0.12,IF(F16<=201050,23200*0.1+71100*0.12+(F16-94300)*0.22,IF(F16<=383900,23200*0.1+71100*0.12+106750*0.22+(F16-201050)*0.24,23200*0.1+71100*0.12+106750*0.22+182850*0.24+(F16-383900)*0.32))))) -> 27737 | H16: =IFERROR(G16/F16,0) -> 0.16215726 | I16: =IF(F16<=206000,"Tier 0 — $0/yr",IF(F16<=258000,"Tier 1 — $594/yr",IF(F16<=322000,"Tier 2 — $1,494/yr",IF(F16<=386000,"Tier 3 — $2,394/yr",IF(F16<=750000,"Tier 4 — $3,270/yr","Tier 5 — $3,564/yr"))))) -> Tier 0 — $0/yr | J16: =MAX(0,B16-E16) -> 1164218.6
A17: 79 | B17: =J16 -> 1164218.6 | C17: =IF(79>=Inputs!B25,IF(Inputs!B25=65,Inputs!B22*12,IF(Inputs!B25=70,Inputs!B24*12,Inputs!B23*12))*(1+Inputs!B21)^MAX(0,79-Inputs!B25),0) -> 64102.781 | D17: =C17*Inputs!B43 -> 54487.364 | E17: =MAX(0,Inputs!B41-D17-Inputs!B42) -> 116562.64 | F17: =D17+E17 -> 171050 | G17: =MAX(0,IF(F17<=23200,F17*0.1,IF(F17<=94300,23200*0.1+(F17-23200)*0.12,IF(F17<=201050,23200*0.1+71100*0.12+(F17-94300)*0.22,IF(F17<=383900,23200*0.1+71100*0.12+106750*0.22+(F17-201050)*0.24,23200*0.1+71100*0.12+106750*0.22+182850*0.24+(F17-383900)*0.32))))) -> 27737 | H17: =IFERROR(G17/F17,0) -> 0.16215726 | I17: =IF(F17<=206000,"Tier 0 — $0/yr",IF(F17<=258000,"Tier 1 — $594/yr",IF(F17<=322000,"Tier 2 — $1,494/yr",IF(F17<=386000,"Tier 3 — $2,394/yr",IF(F17<=750000,"Tier 4 — $3,270/yr","Tier 5 — $3,564/yr"))))) -> Tier 0 — $0/yr | J17: =MAX(0,B17-E17) -> 1047655.9
A18: 80 | B18: =J17 -> 1047655.9 | C18: =IF(80>=Inputs!B25,IF(Inputs!B25=65,Inputs!B22*12,IF(Inputs!B25=70,Inputs!B24*12,Inputs!B23*12))*(1+Inputs!B21)^MAX(0,80-Inputs!B25),0) -> 65705.35 | D18: =C18*Inputs!B43 -> 55849.548 | E18: =MAX(0,Inputs!B41-D18-Inputs!B42) -> 115200.45 | F18: =D18+E18 -> 171050 | G18: =MAX(0,IF(F18<=23200,F18*0.1,IF(F18<=94300,23200*0.1+(F18-23200)*0.12,IF(F18<=201050,23200*0.1+71100*0.12+(F18-94300)*0.22,IF(F18<=383900,23200*0.1+71100*0.12+106750*0.22+(F18-201050)*0.24,23200*0.1+71100*0.12+106750*0.22+182850*0.24+(F18-383900)*0.32))))) -> 27737 | H18: =IFERROR(G18/F18,0) -> 0.16215726 | I18: =IF(F18<=206000,"Tier 0 — $0/yr",IF(F18<=258000,"Tier 1 — $594/yr",IF(F18<=322000,"Tier 2 — $1,494/yr",IF(F18<=386000,"Tier 3 — $2,394/yr",IF(F18<=750000,"Tier 4 — $3,270/yr","Tier 5 — $3,564/yr"))))) -> Tier 0 — $0/yr | J18: =MAX(0,B18-E18) -> 932455.46
A19: 81 | B19: =J18 -> 932455.46 | C19: =IF(81>=Inputs!B25,IF(Inputs!B25=65,Inputs!B22*12,IF(Inputs!B25=70,Inputs!B24*12,Inputs!B23*12))*(1+Inputs!B21)^MAX(0,81-Inputs!B25),0) -> 67347.984 | D19: =C19*Inputs!B43 -> 57245.787 | E19: =MAX(0,Inputs!B41-D19-Inputs!B42) -> 113804.21 | F19: =D19+E19 -> 171050 | G19: =MAX(0,IF(F19<=23200,F19*0.1,IF(F19<=94300,23200*0.1+(F19-23200)*0.12,IF(F19<=201050,23200*0.1+71100*0.12+(F19-94300)*0.22,IF(F19<=383900,23200*0.1+71100*0.12+106750*0.22+(F19-201050)*0.24,23200*0.1+71100*0.12+106750*0.22+182850*0.24+(F19-383900)*0.32))))) -> 27737 | H19: =IFERROR(G19/F19,0) -> 0.16215726 | I19: =IF(F19<=206000,"Tier 0 — $0/yr",IF(F19<=258000,"Tier 1 — $594/yr",IF(F19<=322000,"Tier 2 — $1,494/yr",IF(F19<=386000,"Tier 3 — $2,394/yr",IF(F19<=750000,"Tier 4 — $3,270/yr","Tier 5 — $3,564/yr"))))) -> Tier 0 — $0/yr | J19: =MAX(0,B19-E19) -> 818651.25
A20: 82 | B20: =J19 -> 818651.25 | C20: =IF(82>=Inputs!B25,IF(Inputs!B25=65,Inputs!B22*12,IF(Inputs!B25=70,Inputs!B24*12,Inputs!B23*12))*(1+Inputs!B21)^MAX(0,82-Inputs!B25),0) -> 69031.684 | D20: =C20*Inputs!B43 -> 58676.931 | E20: =MAX(0,Inputs!B41-D20-Inputs!B42) -> 112373.07 | F20: =D20+E20 -> 171050 | G20: =MAX(0,IF(F20<=23200,F20*0.1,IF(F20<=94300,23200*0.1+(F20-23200)*0.12,IF(F20<=201050,23200*0.1+71100*0.12+(F20-94300)*0.22,IF(F20<=383900,23200*0.1+71100*0.12+106750*0.22+(F20-201050)*0.24,23200*0.1+71100*0.12+106750*0.22+182850*0.24+(F20-383900)*0.32))))) -> 27737 | H20: =IFERROR(G20/F20,0) -> 0.16215726 | I20: =IF(F20<=206000,"Tier 0 — $0/yr",IF(F20<=258000,"Tier 1 — $594/yr",IF(F20<=322000,"Tier 2 — $1,494/yr",IF(F20<=386000,"Tier 3 — $2,394/yr",IF(F20<=750000,"Tier 4 — $3,270/yr","Tier 5 — $3,564/yr"))))) -> Tier 0 — $0/yr | J20: =MAX(0,B20-E20) -> 706278.18
A21: 83 | B21: =J20 -> 706278.18 | C21: =IF(83>=Inputs!B25,IF(Inputs!B25=65,Inputs!B22*12,IF(Inputs!B25=70,Inputs!B24*12,Inputs!B23*12))*(1+Inputs!B21)^MAX(0,83-Inputs!B25),0) -> 70757.476 | D21: =C21*Inputs!B43 -> 60143.855 | E21: =MAX(0,Inputs!B41-D21-Inputs!B42) -> 110906.15 | F21: =D21+E21 -> 171050 | G21: =MAX(0,IF(F21<=23200,F21*0.1,IF(F21<=94300,23200*0.1+(F21-23200)*0.12,IF(F21<=201050,23200*0.1+71100*0.12+(F21-94300)*0.22,IF(F21<=383900,23200*0.1+71100*0.12+106750*0.22+(F21-201050)*0.24,23200*0.1+71100*0.12+106750*0.22+182850*0.24+(F21-383900)*0.32))))) -> 27737 | H21: =IFERROR(G21/F21,0) -> 0.16215726 | I21: =IF(F21<=206000,"Tier 0 — $0/yr",IF(F21<=258000,"Tier 1 — $594/yr",IF(F21<=322000,"Tier 2 — $1,494/yr",IF(F21<=386000,"Tier 3 — $2,394/yr",IF(F21<=750000,"Tier 4 — $3,270/yr","Tier 5 — $3,564/yr"))))) -> Tier 0 — $0/yr | J21: =MAX(0,B21-E21) -> 595372.04
A22: 84 | B22: =J21 -> 595372.04 | C22: =IF(84>=Inputs!B25,IF(Inputs!B25=65,Inputs!B22*12,IF(Inputs!B25=70,Inputs!B24*12,Inputs!B23*12))*(1+Inputs!B21)^MAX(0,84-Inputs!B25),0) -> 72526.413 | D22: =C22*Inputs!B43 -> 61647.451 | E22: =MAX(0,Inputs!B41-D22-Inputs!B42) -> 109402.55 | F22: =D22+E22 -> 171050 | G22: =MAX(0,IF(F22<=23200,F22*0.1,IF(F22<=94300,23200*0.1+(F22-23200)*0.12,IF(F22<=201050,23200*0.1+71100*0.12+(F22-94300)*0.22,IF(F22<=383900,23200*0.1+71100*0.12+106750*0.22+(F22-201050)*0.24,23200*0.1+71100*0.12+106750*0.22+182850*0.24+(F22-383900)*0.32))))) -> 27737 | H22: =IFERROR(G22/F22,0) -> 0.16215726 | I22: =IF(F22<=206000,"Tier 0 — $0/yr",IF(F22<=258000,"Tier 1 — $594/yr",IF(F22<=322000,"Tier 2 — $1,494/yr",IF(F22<=386000,"Tier 3 — $2,394/yr",IF(F22<=750000,"Tier 4 — $3,270/yr","Tier 5 — $3,564/yr"))))) -> Tier 0 — $0/yr | J22: =MAX(0,B22-E22) -> 485969.49
A23: 85 | B23: =J22 -> 485969.49 | C23: =IF(85>=Inputs!B25,IF(Inputs!B25=65,Inputs!B22*12,IF(Inputs!B25=70,Inputs!B24*12,Inputs!B23*12))*(1+Inputs!B21)^MAX(0,85-Inputs!B25),0) -> 74339.573 | D23: =C23*Inputs!B43 -> 63188.637 | E23: =MAX(0,Inputs!B41-D23-Inputs!B42) -> 107861.36 | F23: =D23+E23 -> 171050 | G23: =MAX(0,IF(F23<=23200,F23*0.1,IF(F23<=94300,23200*0.1+(F23-23200)*0.12,IF(F23<=201050,23200*0.1+71100*0.12+(F23-94300)*0.22,IF(F23<=383900,23200*0.1+71100*0.12+106750*0.22+(F23-201050)*0.24,23200*0.1+71100*0.12+106750*0.22+182850*0.24+(F23-383900)*0.32))))) -> 27737 | H23: =IFERROR(G23/F23,0) -> 0.16215726 | I23: =IF(F23<=206000,"Tier 0 — $0/yr",IF(F23<=258000,"Tier 1 — $594/yr",IF(F23<=322000,"Tier 2 — $1,494/yr",IF(F23<=386000,"Tier 3 — $2,394/yr",IF(F23<=750000,"Tier 4 — $3,270/yr","Tier 5 — $3,564/yr"))))) -> Tier 0 — $0/yr | J23: =MAX(0,B23-E23) -> 378108.12
A25: IRMAA 2025 Tier Legend (MFJ, per-person surcharge/yr):
A26: Base (Tier 0): MAGI ≤ $206,000 — $0 surcharge
A27: Tier 1: MAGI $206,001–$258,000 — $594/person/yr
A28: Tier 2: MAGI $258,001–$322,000 — $1,488/person/yr
A29: Tier 3: MAGI $322,001–$386,000 — $2,382/person/yr
A30: Tier 4: MAGI $386,001–$750,000 — $3,276/person/yr
A31: Tier 5: MAGI > $750,000 — $4,170/person/yr

Sheet Withdrawal Plan
A1: ANNUAL WITHDRAWAL PLAN (Ages 65–85)
A2: Age | B2: Living+Infl ($) | C2: Mortgage ($) [ends at term] | D2: Prop Tax +Ins ($) | E2: Wife Ins ($) | F2: Medicare ($) | G2: Total Needs ($) | H2: Your SS ($) | I2: Wife SS ($) | J2: Trad 401k Draw ($) | K2: Roth IRA Draw ($) | L2: Brokerage Draw ($) | M2: HSA Draw ($) | N2: Fed Tax ($) | O2: State Tax ($) | P2: Net Surplus ($)
A3: 65 | B3: =Inputs!B29*12*(1+Inputs!B20)^0 -> 84000 | C3: =IF(Inputs!B51=1,0,IF((VALUE(A3)-Inputs!B5)>=MAX(0,Inputs!B48-(Inputs!B5-Inputs!B4)),0,Inputs!B30*12)) -> 36000 | D3: =Inputs!B31+Inputs!B32 -> 16500 | E3: =IF(60<65,Inputs!B35*12,0) -> 9600 | F3: =Inputs!B33*12*(1+Inputs!B34)^0 -> 2220 | G3: =B3+C3+D3+E3+F3 -> 148320 | H3: =IF(65>=Inputs!B25,IF(Inputs!B25=65,Inputs!B22*12,IF(Inputs!B25=70,Inputs!B24*12,Inputs!B23*12))*(1+Inputs!B21)^MAX(0,65-Inputs!B25),0) -> 0 | I3: =IF(60>=Inputs!B26,Inputs!B23*12*0.5*(1+Inputs!B21)^MAX(0,60-Inputs!B26),0) -> 0 | J3: ='Roth Conversion'!E3 -> 171050 | K3: =MAX(0,G3-H3-I3-J3)*0.4 -> 0 | L3: =MAX(0,G3-H3-I3-J3-K3) -> 0 | M3: =F3 -> 2220 | N3: =MAX(0,IF((J3+H3*Inputs!B43)<=23200,(J3+H3*Inputs!B43)*0.1,IF((J3+H3*Inputs!B43)<=94300,23200*0.1+((J3+H3*Inputs!B43)-23200)*0.12,IF((J3+H3*Inputs!B43)<=201050,23200*0.1+71100*0.12+((J3+H3*Inputs!B43)-94300)*0.22,23200*0.1+71100*0.12+106750*0.22+((J3+H3*Inputs!B43)-201050)*0.24)))) -> 27737 | O3: =J3*0.0637 -> 10895.885 | P3: =H3+I3+J3+K3+L3-G3-N3-O3 -> -15902.885
A4: 66 | B4: =Inputs!B29*12*(1+Inputs!B20)^1 -> 86520 | C4: =IF(Inputs!B51=1,0,IF((VALUE(A4)-Inputs!B5)>=MAX(0,Inputs!B48-(Inputs!B5-Inputs!B4)),0,Inputs!B30*12)) -> 36000 | D4: =Inputs!B31+Inputs!B32 -> 16500 | E4: =IF(61<65,Inputs!B35*12,0) -> 9600 | F4: =Inputs!B33*12*(1+Inputs!B34)^1 -> 2331 | G4: =B4+C4+D4+E4+F4 -> 150951 | H4: =IF(66>=Inputs!B25,IF(Inputs!B25=65,Inputs!B22*12,IF(Inputs!B25=70,Inputs!B24*12,Inputs!B23*12))*(1+Inputs!B21)^MAX(0,66-Inputs!B25),0) -> 0 | I4: =IF(61>=Inputs!B26,Inputs!B23*12*0.5*(1+Inputs!B21)^MAX(0,61-Inputs!B26),0) -> 0 | J4: ='Roth Conversion'!E4 -> 171050 | K4: =MAX(0,G4-H4-I4-J4)*0.4 -> 0 | L4: =MAX(0,G4-H4-I4-J4-K4) -> 0 | M4: =F4 -> 2331 | N4: =MAX(0,IF((J4+H4*Inputs!B43)<=23200,(J4+H4*Inputs!B43)*0.1,IF((J4+H4*Inputs!B43)<=94300,23200*0.1+((J4+H4*Inputs!B43)-23200)*0.12,IF((J4+H4*Inputs!B43)<=201050,23200*0.1+71100*0.12+((J4+H4*Inputs!B43)-94300)*0.22,23200*0.1+71100*0.12+106750*0.22+((J4+H4*Inputs!B43)-201050)*0.24)))) -> 27737 | O4: =J4*0.0637 -> 10895.885 | P4: =H4+I4+J4+K4+L4-G4-N4-O4 -> -18533.885
A5: 67 | B5: =Inputs!B29*12*(1+Inputs!B20)^2 -> 89115.6 | C5: =IF(Inputs!B51=1,0,IF((VALUE(A5)-Inputs!B5)>=MAX(0,Inputs!B48-(Inputs!B5-Inputs!B4)),0,Inputs!B30*12)) -> 36000 | D5: =Inputs!B31+Inputs!B32 -> 16500 | E5: =IF(62<65,Inputs!B35*12,0) -> 9600 | F5: =Inputs!B33*12*(1+Inputs!B34)^2 -> 2447.55 | G5: =B5+C5+D5+E5+F5 -> 153663.15 | H5: =IF(67>=Inputs!B25,IF(Inputs!B25=65,Inputs!B22*12,IF(Inputs!B25=70,Inputs!B24*12,Inputs!B23*12))*(1+Inputs!B21)^MAX(0,67-Inputs!B25),0) -> 47664 | I5: =IF(62>=Inputs!B26,Inputs!B23*12*0.5*(1+Inputs!B21)^MAX(0,62-Inputs!B26),0) -> 0 | J5: ='Roth Conversion'!E5 -> 130535.6 | K5: =MAX(0,G5-H5-I5-J5)*0.4 -> 0 | L5: =MAX(0,G5-H5-I5-J5-K5) -> 0 | M5: =F5 -> 2447.55 | N5: =MAX(0,IF((J5+H5*Inputs!B43)<=23200,(J5+H5*Inputs!B43)*0.1,IF((J5+H5*Inputs!B43)<=94300,23200*0.1+((J5+H5*Inputs!B43)-23200)*0.12,IF((J5+H5*Inputs!B43)<=201050,23200*0.1+71100*0.12+((J5+H5*Inputs!B43)-94300)*0.22,23200*0.1+71100*0.12+106750*0.22+((J5+H5*Inputs!B43)-201050)*0.24)))) -> 27737 | O5: =J5*0.0637 -> 8315.1177 | P5: =H5+I5+J5+K5+L5-G5-N5-O5 -> -11515.668
A6: 68 | B6: =Inputs!B29*12*(1+Inputs!B20)^3 -> 91789.068 | C6: =IF(Inputs!B51=1,0,IF((VALUE(A6)-Inputs!B5)>=MAX(0,Inputs!B48-(Inputs!B5-Inputs!B4)),0,Inputs!B30*12)) -> 36000 | D6: =Inputs!B31+Inputs!B32 -> 16500 | E6: =IF(63<65,Inputs!B35*12,0) -> 9600 | F6: =Inputs!B33*12*(1+Inputs!B34)^3 -> 2569.9275 | G6: =B6+C6+D6+E6+F6 -> 156459 | H6: =IF(68>=Inputs!B25,IF(Inputs!B25=65,Inputs!B22*12,IF(Inputs!B25=70,Inputs!B24*12,Inputs!B23*12))*(1+Inputs!B21)^MAX(0,68-Inputs!B25),0) -> 48855.6 | I6: =IF(63>=Inputs!B26,Inputs!B23*12*0.5*(1+Inputs!B21)^MAX(0,63-Inputs!B26),0) -> 0 | J6: ='Roth Conversion'!E6 -> 129522.74 | K6: =MAX(0,G6-H6-I6-J6)*0.4 -> 0 | L6: =MAX(0,G6-H6-I6-J6-K6) -> 0 | M6: =F6 -> 2569.9275 | N6: =MAX(0,IF((J6+H6*Inputs!B43)<=23200,(J6+H6*Inputs!B43)*0.1,IF((J6+H6*Inputs!B43)<=94300,23200*0.1+((J6+H6*Inputs!B43)-23200)*0.12,IF((J6+H6*Inputs!B43)<=201050,23200*0.1+71100*0.12+((J6+H6*Inputs!B43)-94300)*0.22,23200*0.1+71100*0.12+106750*0.22+((J6+H6*Inputs!B43)-201050)*0.24)))) -> 27737 | O6: =J6*0.0637 -> 8250.5985 | P6: =H6+I6+J6+K6+L6-G6-N6-O6 -> -14068.254
A7: 69 | B7: =Inputs!B29*12*(1+Inputs!B20)^4 -> 94542.74 | C7: =IF(Inputs!B51=1,0,IF((VALUE(A7)-Inputs!B5)>=MAX(0,Inputs!B48-(Inputs!B5-Inputs!B4)),0,Inputs!B30*12)) -> 36000 | D7: =Inputs!B31+Inputs!B32 -> 16500 | E7: =IF(64<65,Inputs!B35*12,0) -> 9600 | F7: =Inputs!B33*12*(1+Inputs!B34)^4 -> 2698.4239 | G7: =B7+C7+D7+E7+F7 -> 159341.16 | H7: =IF(69>=Inputs!B25,IF(Inputs!B25=65,Inputs!B22*12,IF(Inputs!B25=70,Inputs!B24*12,Inputs!B23*12))*(1+Inputs!B21)^MAX(0,69-Inputs!B25),0) -> 50076.99 | I7: =IF(64>=Inputs!B26,Inputs!B23*12*0.5*(1+Inputs!B21)^MAX(0,64-Inputs!B26),0) -> 0 | J7: ='Roth Conversion'!E7 -> 128484.56 | K7: =MAX(0,G7-H7-I7-J7)*0.4 -> 0 | L7: =MAX(0,G7-H7-I7-J7-K7) -> 0 | M7: =F7 -> 2698.4239 | N7: =MAX(0,IF((J7+H7*Inputs!B43)<=23200,(J7+H7*Inputs!B43)*0.1,IF((J7+H7*Inputs!B43)<=94300,23200*0.1+((J7+H7*Inputs!B43)-23200)*0.12,IF((J7+H7*Inputs!B43)<=201050,23200*0.1+71100*0.12+((J7+H7*Inputs!B43)-94300)*0.22,23200*0.1+71100*0.12+106750*0.22+((J7+H7*Inputs!B43)-201050)*0.24)))) -> 27737 | O7: =J7*0.0637 -> 8184.4664 | P7: =H7+I7+J7+K7+L7-G7-N7-O7 -> -16701.082
A8: 70 | B8: =Inputs!B29*12*(1+Inputs!B20)^5 -> 97379.022 | C8: =IF(Inputs!B51=1,0,IF((VALUE(A8)-Inputs!B5)>=MAX(0,Inputs!B48-(Inputs!B5-Inputs!B4)),0,Inputs!B30*12)) -> 36000 | D8: =Inputs!B31+Inputs!B32 -> 16500 | E8: =IF(65<65,Inputs!B35*12,0) -> 0 | F8: =Inputs!B33*12*(1+Inputs!B34)^5 -> 2833.3451 | G8: =B8+C8+D8+E8+F8 -> 152712.37 | H8: =IF(70>=Inputs!B25,IF(Inputs!B25=65,Inputs!B22*12,IF(Inputs!B25=70,Inputs!B24*12,Inputs!B23*12))*(1+Inputs!B21)^MAX(0,70-Inputs!B25),0) -> 51328.915 | I8: =IF(65>=Inputs!B26,Inputs!B23*12*0.5*(1+Inputs!B21)^MAX(0,65-Inputs!B26),0) -> 23832 | J8: ='Roth Conversion'!E8 -> 127420.42 | K8: =MAX(0,G8-H8-I8-J8)*0.4 -> 0 | L8: =MAX(0,G8-H8-I8-J8-K8) -> 0 | M8: =F8 -> 2833.3451 | N8: =MAX(0,IF((J8+H8*Inputs!B43)<=23200,(J8+H8*Inputs!B43)*0.1,IF((J8+H8*Inputs!B43)<=94300,23200*0.1+((J8+H8*Inputs!B43)-23200)*0.12,IF((J8+H8*Inputs!B43)<=201050,23200*0.1+71100*0.12+((J8+H8*Inputs!B43)-94300)*0.22,23200*0.1+71100*0.12+106750*0.22+((J8+H8*Inputs!B43)-201050)*0.24)))) -> 27737 | O8: =J8*0.0637 -> 8116.6809 | P8: =H8+I8+J8+K8+L8-G8-N8-O8 -> 14015.289
A9: 71 | B9: =Inputs!B29*12*(1+Inputs!B20)^6 -> 100300.39 | C9: =IF(Inputs!B51=1,0,IF((VALUE(A9)-Inputs!B5)>=MAX(0,Inputs!B48-(Inputs!B5-Inputs!B4)),0,Inputs!B30*12)) -> 36000 | D9: =Inputs!B31+Inputs!B32 -> 16500 | E9: =IF(66<65,Inputs!B35*12,0) -> 0 | F9: =Inputs!B33*12*(1+Inputs!B34)^6 -> 2975.0123 | G9: =B9+C9+D9+E9+F9 -> 155775.41 | H9: =IF(71>=Inputs!B25,IF(Inputs!B25=65,Inputs!B22*12,IF(Inputs!B25=70,Inputs!B24*12,Inputs!B23*12))*(1+Inputs!B21)^MAX(0,71-Inputs!B25),0) -> 52612.138 | I9: =IF(66>=Inputs!B26,Inputs!B23*12*0.5*(1+Inputs!B21)^MAX(0,66-Inputs!B26),0) -> 24427.8 | J9: ='Roth Conversion'!E9 -> 126329.68 | K9: =MAX(0,G9-H9-I9-J9)*0.4 -> 0 | L9: =MAX(0,G9-H9-I9-J9-K9) -> 0 | M9: =F9 -> 2975.0123 | N9: =MAX(0,IF((J9+H9*Inputs!B43)<=23200,(J9+H9*Inputs!B43)*0.1,IF((J9+H9*Inputs!B43)<=94300,23200*0.1+((J9+H9*Inputs!B43)-23200)*0.12,IF((J9+H9*Inputs!B43)<=201050,23200*0.1+71100*0.12+((J9+H9*Inputs!B43)-94300)*0.22,23200*0.1+71100*0.12+106750*0.22+((J9+H9*Inputs!B43)-201050)*0.24)))) -> 27737 | O9: =J9*0.0637 -> 8047.2008 | P9: =H9+I9+J9+K9+L9-G9-N9-O9 -> 11810.015
A10: 72 | B10: =Inputs!B29*12*(1+Inputs!B20)^7 -> 103309.4 | C10: =IF(Inputs!B51=1,0,IF((VALUE(A10)-Inputs!B5)>=MAX(0,Inputs!B48-(Inputs!B5-Inputs!B4)),0,Inputs!B30*12)) -> 36000 | D10: =Inputs!B31+Inputs!B32 -> 16500 | E10: =IF(67<65,Inputs!B35*12,0) -> 0 | F10: =Inputs!B33*12*(1+Inputs!B34)^7 -> 3123.7629 | G10: =B10+C10+D10+E10+F10 -> 158933.17 | H10: =IF(72>=Inputs!B25,IF(Inputs!B25=65,Inputs!B22*12,IF(Inputs!B25=70,Inputs!B24*12,Inputs!B23*12))*(1+Inputs!B21)^MAX(0,72-Inputs!B25),0) -> 53927.441 | I10: =IF(67>=Inputs!B26,Inputs!B23*12*0.5*(1+Inputs!B21)^MAX(0,67-Inputs!B26),0) -> 25038.495 | J10: ='Roth Conversion'!E10 -> 125211.68 | K10: =MAX(0,G10-H10-I10-J10)*0.4 -> 0 | L10: =MAX(0,G10-H10-I10-J10-K10) -> 0 | M10: =F10 -> 3123.7629 | N10: =MAX(0,IF((J10+H10*Inputs!B43)<=23200,(J10+H10*Inputs!B43)*0.1,IF((J10+H10*Inputs!B43)<=94300,23200*0.1+((J10+H10*Inputs!B43)-23200)*0.12,IF((J10+H10*Inputs!B43)<=201050,23200*0.1+71100*0.12+((J10+H10*Inputs!B43)-94300)*0.22,23200*0.1+71100*0.12+106750*0.22+((J10+H10*Inputs!B43)-201050)*0.24)))) -> 27737 | O10: =J10*0.0637 -> 7975.9837 | P10: =H10+I10+J10+K10+L10-G10-N10-O10 -> 9531.4598
A11: 73 | B11: =Inputs!B29*12*(1+Inputs!B20)^8 -> 106408.69 | C11: =IF(Inputs!B51=1,0,IF((VALUE(A11)-Inputs!B5)>=MAX(0,Inputs!B48-(Inputs!B5-Inputs!B4)),0,Inputs!B30*12)) -> 36000 | D11: =Inputs!B31+Inputs!B32 -> 16500 | E11: =IF(68<65,Inputs!B35*12,0) -> 0 | F11: =Inputs!B33*12*(1+Inputs!B34)^8 -> 3279.9511 | G11: =B11+C11+D11+E11+F11 -> 162188.64 | H11: =IF(73>=Inputs!B25,IF(Inputs!B25=65,Inputs!B22*12,IF(Inputs!B25=70,Inputs!B24*12,Inputs!B23*12))*(1+Inputs!B21)^MAX(0,73-Inputs!B25),0) -> 55275.627 | I11: =IF(68>=Inputs!B26,Inputs!B23*12*0.5*(1+Inputs!B21)^MAX(0,68-Inputs!B26),0) -> 25664.457 | J11: ='Roth Conversion'!E11 -> 124065.72 | K11: =MAX(0,G11-H11-I11-J11)*0.4 -> 0 | L11: =MAX(0,G11-H11-I11-J11-K11) -> 0 | M11: =F11 -> 3279.9511 | N11: =MAX(0,IF((J11+H11*Inputs!B43)<=23200,(J11+H11*Inputs!B43)*0.1,IF((J11+H11*Inputs!B43)<=94300,23200*0.1+((J11+H11*Inputs!B43)-23200)*0.12,IF((J11+H11*Inputs!B43)<=201050,23200*0.1+71100*0.12+((J11+H11*Inputs!B43)-94300)*0.22,23200*0.1+71100*0.12+106750*0.22+((J11+H11*Inputs!B43)-201050)*0.24)))) -> 27737 | O11: =J11*0.0637 -> 7902.9862 | P11: =H11+I11+J11+K11+L11-G11-N11-O11 -> 7177.1773
A12: 74 | B12: =Inputs!B29*12*(1+Inputs!B20)^9 -> 109600.95 | C12: =IF(Inputs!B51=1,0,IF((VALUE(A12)-Inputs!B5)>=MAX(0,Inputs!B48-(Inputs!B5-Inputs!B4)),0,Inputs!B30*12)) -> 36000 | D12: =Inputs!B31+Inputs!B32 -> 16500 | E12: =IF(69<65,Inputs!B35*12,0) -> 0 | F12: =Inputs!B33*12*(1+Inputs!B34)^9 -> 3443.9486 | G12: =B12+C12+D12+E12+F12 -> 165544.9 | H12: =IF(74>=Inputs!B25,IF(Inputs!B25=65,Inputs!B22*12,IF(Inputs!B25=70,Inputs!B24*12,Inputs!B23*12))*(1+Inputs!B21)^MAX(0,74-Inputs!B25),0) -> 56657.518 | I12: =IF(69>=Inputs!B26,Inputs!B23*12*0.5*(1+Inputs!B21)^MAX(0,69-Inputs!B26),0) -> 26306.069 | J12: ='Roth Conversion'!E12 -> 122891.11 | K12: =MAX(0,G12-H12-I12-J12)*0.4 -> 0 | L12: =MAX(0,G12-H12-I12-J12-K12) -> 0 | M12: =F12 -> 3443.9486 | N12: =MAX(0,IF((J12+H12*Inputs!B43)<=23200,(J12+H12*Inputs!B43)*0.1,IF((J12+H12*Inputs!B43)<=94300,23200*0.1+((J12+H12*Inputs!B43)-23200)*0.12,IF((J12+H12*Inputs!B43)<=201050,23200*0.1+71100*0.12+((J12+H12*Inputs!B43)-94300)*0.22,23200*0.1+71100*0.12+106750*0.22+((J12+H12*Inputs!B43)-201050)*0.24)))) -> 27737 | O12: =J12*0.0637 -> 7828.1637 | P12: =H12+I12+J12+K12+L12-G12-N12-O12 -> 4744.6367
A13: 75 | B13: =Inputs!B29*12*(1+Inputs!B20)^10 -> 112888.98 | C13: =IF(Inputs!B51=1,0,IF((VALUE(A13)-Inputs!B5)>=MAX(0,Inputs!B48-(Inputs!B5-Inputs!B4)),0,Inputs!B30*12)) -> 36000 | D13: =Inputs!B31+Inputs!B32 -> 16500 | E13: =IF(70<65,Inputs!B35*12,0) -> 0 | F13: =Inputs!B33*12*(1+Inputs!B34)^10 -> 3616.1461 | G13: =B13+C13+D13+E13+F13 -> 169005.12 | H13: =IF(75>=Inputs!B25,IF(Inputs!B25=65,Inputs!B22*12,IF(Inputs!B25=70,Inputs!B24*12,Inputs!B23*12))*(1+Inputs!B21)^MAX(0,75-Inputs!B25),0) -> 58073.956 | I13: =IF(70>=Inputs!B26,Inputs!B23*12*0.5*(1+Inputs!B21)^MAX(0,70-Inputs!B26),0) -> 26963.721 | J13: ='Roth Conversion'!E13 -> 121687.14 | K13: =MAX(0,G13-H13-I13-J13)*0.4 -> 0 | L13: =MAX(0,G13-H13-I13-J13-K13) -> 0 | M13: =F13 -> 3616.1461 | N13: =MAX(0,IF((J13+H13*Inputs!B43)<=23200,(J13+H13*Inputs!B43)*0.1,IF((J13+H13*Inputs!B43)<=94300,23200*0.1+((J13+H13*Inputs!B43)-23200)*0.12,IF((J13+H13*Inputs!B43)<=201050,23200*0.1+71100*0.12+((J13+H13*Inputs!B43)-94300)*0.22,23200*0.1+71100*0.12+106750*0.22+((J13+H13*Inputs!B43)-201050)*0.24)))) -> 27737 | O13: =J13*0.0637 -> 7751.4707 | P13: =H13+I13+J13+K13+L13-G13-N13-O13 -> 2231.2213
A14: 76 | B14: =Inputs!B29*12*(1+Inputs!B20)^11 -> 116275.65 | C14: =IF(Inputs!B51=1,0,IF((VALUE(A14)-Inputs!B5)>=MAX(0,Inputs!B48-(Inputs!B5-Inputs!B4)),0,Inputs!B30*12)) -> 36000 | D14: =Inputs!B31+Inputs!B32 -> 16500 | E14: =IF(71<65,Inputs!B35*12,0) -> 0 | F14: =Inputs!B33*12*(1+Inputs!B34)^11 -> 3796.9534 | G14: =B14+C14+D14+E14+F14 -> 172572.6 | H14: =IF(76>=Inputs!B25,IF(Inputs!B25=65,Inputs!B22*12,IF(Inputs!B25=70,Inputs!B24*12,Inputs!B23*12))*(1+Inputs!B21)^MAX(0,76-Inputs!B25),0) -> 59525.805 | I14: =IF(71>=Inputs!B26,Inputs!B23*12*0.5*(1+Inputs!B21)^MAX(0,71-Inputs!B26),0) -> 27637.814 | J14: ='Roth Conversion'!E14 -> 120453.07 | K14: =MAX(0,G14-H14-I14-J14)*0.4 -> 0 | L14: =MAX(0,G14-H14-I14-J14-K14) -> 0 | M14: =F14 -> 3796.9534 | N14: =MAX(0,IF((J14+H14*Inputs!B43)<=23200,(J14+H14*Inputs!B43)*0.1,IF((J14+H14*Inputs!B43)<=94300,23200*0.1+((J14+H14*Inputs!B43)-23200)*0.12,IF((J14+H14*Inputs!B43)<=201050,23200*0.1+71100*0.12+((J14+H14*Inputs!B43)-94300)*0.22,23200*0.1+71100*0.12+106750*0.22+((J14+H14*Inputs!B43)-201050)*0.24)))) -> 27737 | O14: =J14*0.0637 -> 7672.8603 | P14: =H14+I14+J14+K14+L14-G14-N14-O14 -> -365.77459
A15: 77 | B15: =Inputs!B29*12*(1+Inputs!B20)^12 -> 119763.91 | C15: =IF(Inputs!B51=1,0,IF((VALUE(A15)-Inputs!B5)>=MAX(0,Inputs!B48-(Inputs!B5-Inputs!B4)),0,Inputs!B30*12)) -> 36000 | D15: =Inputs!B31+Inputs!B32 -> 16500 | E15: =IF(72<65,Inputs!B35*12,0) -> 0 | F15: =Inputs!B33*12*(1+Inputs!B34)^12 -> 3986.801 | G15: =B15+C15+D15+E15+F15 -> 176250.72 | H15: =IF(77>=Inputs!B25,IF(Inputs!B25=65,Inputs!B22*12,IF(Inputs!B25=70,Inputs!B24*12,Inputs!B23*12))*(1+Inputs!B21)^MAX(0,77-Inputs!B25),0) -> 61013.95 | I15: =IF(72>=Inputs!B26,Inputs!B23*12*0.5*(1+Inputs!B21)^MAX(0,72-Inputs!B26),0) -> 28328.759 | J15: ='Roth Conversion'!E15 -> 119188.14 | K15: =MAX(0,G15-H15-I15-J15)*0.4 -> 0 | L15: =MAX(0,G15-H15-I15-J15-K15) -> 0 | M15: =F15 -> 3986.801 | N15: =MAX(0,IF((J15+H15*Inputs!B43)<=23200,(J15+H15*Inputs!B43)*0.1,IF((J15+H15*Inputs!B43)<=94300,23200*0.1+((J15+H15*Inputs!B43)-23200)*0.12,IF((J15+H15*Inputs!B43)<=201050,23200*0.1+71100*0.12+((J15+H15*Inputs!B43)-94300)*0.22,23200*0.1+71100*0.12+106750*0.22+((J15+H15*Inputs!B43)-201050)*0.24)))) -> 27737 | O15: =J15*0.0637 -> 7592.2847 | P15: =H15+I15+J15+K15+L15-G15-N15-O15 -> -3049.1489
A16: 78 | B16: =Inputs!B29*12*(1+Inputs!B20)^13 -> 123356.83 | C16: =IF(Inputs!B51=1,0,IF((VALUE(A16)-Inputs!B5)>=MAX(0,Inputs!B48-(Inputs!B5-Inputs!B4)),0,Inputs!B30*12)) -> 0 | D16: =Inputs!B31+Inputs!B32 -> 16500 | E16: =IF(73<65,Inputs!B35*12,0) -> 0 | F16: =Inputs!B33*12*(1+Inputs!B34)^13 -> 4186.1411 | G16: =B16+C16+D16+E16+F16 -> 144042.97 | H16: =IF(78>=Inputs!B25,IF(Inputs!B25=65,Inputs!B22*12,IF(Inputs!B25=70,Inputs!B24*12,Inputs!B23*12))*(1+Inputs!B21)^MAX(0,78-Inputs!B25),0) -> 62539.298 | I16: =IF(73>=Inputs!B26,Inputs!B23*12*0.5*(1+Inputs!B21)^MAX(0,73-Inputs!B26),0) -> 29036.978 | J16: ='Roth Conversion'!E16 -> 117891.6 | K16: =MAX(0,G16-H16-I16-J16)*0.4 -> 0 | L16: =MAX(0,G16-H16-I16-J16-K16) -> 0 | M16: =F16 -> 4186.1411 | N16: =MAX(0,IF((J16+H16*Inputs!B43)<=23200,(J16+H16*Inputs!B43)*0.1,IF((J16+H16*Inputs!B43)<=94300,23200*0.1+((J16+H16*Inputs!B43)-23200)*0.12,IF((J16+H16*Inputs!B43)<=201050,23200*0.1+71100*0.12+((J16+H16*Inputs!B43)-94300)*0.22,23200*0.1+71100*0.12+106750*0.22+((J16+H16*Inputs!B43)-201050)*0.24)))) -> 27737 | O16: =J16*0.0637 -> 7509.6947 | P16: =H16+I16+J16+K16+L16-G16-N16-O16 -> 30178.205
A17: 79 | B17: =Inputs!B29*12*(1+Inputs!B20)^14 -> 127057.54 | C17: =IF(Inputs!B51=1,0,IF((VALUE(A17)-Inputs!B5)>=MAX(0,Inputs!B48-(Inputs!B5-Inputs!B4)),0,Inputs!B30*12)) -> 0 | D17: =Inputs!B31+Inputs!B32 -> 16500 | E17: =IF(74<65,Inputs!B35*12,0) -> 0 | F17: =Inputs!B33*12*(1+Inputs!B34)^14 -> 4395.4482 | G17: =B17+C17+D17+E17+F17 -> 147952.99 | H17: =IF(79>=Inputs!B25,IF(Inputs!B25=65,Inputs!B22*12,IF(Inputs!B25=70,Inputs!B24*12,Inputs!B23*12))*(1+Inputs!B21)^MAX(0,79-Inputs!B25),0) -> 64102.781 | I17: =IF(74>=Inputs!B26,Inputs!B23*12*0.5*(1+Inputs!B21)^MAX(0,74-Inputs!B26),0) -> 29762.902 | J17: ='Roth Conversion'!E17 -> 116562.64 | K17: =MAX(0,G17-H17-I17-J17)*0.4 -> 0 | L17: =MAX(0,G17-H17-I17-J17-K17) -> 0 | M17: =F17 -> 4395.4482 | N17: =MAX(0,IF((J17+H17*Inputs!B43)<=23200,(J17+H17*Inputs!B43)*0.1,IF((J17+H17*Inputs!B43)<=94300,23200*0.1+((J17+H17*Inputs!B43)-23200)*0.12,IF((J17+H17*Inputs!B43)<=201050,23200*0.1+71100*0.12+((J17+H17*Inputs!B43)-94300)*0.22,23200*0.1+71100*0.12+106750*0.22+((J17+H17*Inputs!B43)-201050)*0.24)))) -> 27737 | O17: =J17*0.0637 -> 7425.0399 | P17: =H17+I17+J17+K17+L17-G17-N17-O17 -> 27313.294
A18: 80 | B18: =Inputs!B29*12*(1+Inputs!B20)^15 -> 130869.26 | C18: =IF(Inputs!B51=1,0,IF((VALUE(A18)-Inputs!B5)>=MAX(0,Inputs!B48-(Inputs!B5-Inputs!B4)),0,Inputs!B30*12)) -> 0 | D18: =Inputs!B31+Inputs!B32 -> 16500 | E18: =IF(75<65,Inputs!B35*12,0) -> 0 | F18: =Inputs!B33*12*(1+Inputs!B34)^15 -> 4615.2206 | G18: =B18+C18+D18+E18+F18 -> 151984.48 | H18: =IF(80>=Inputs!B25,IF(Inputs!B25=65,Inputs!B22*12,IF(Inputs!B25=70,Inputs!B24*12,Inputs!B23*12))*(1+Inputs!B21)^MAX(0,80-Inputs!B25),0) -> 65705.35 | I18: =IF(75>=Inputs!B26,Inputs!B23*12*0.5*(1+Inputs!B21)^MAX(0,75-Inputs!B26),0) -> 30506.975 | J18: ='Roth Conversion'!E18 -> 115200.45 | K18: =MAX(0,G18-H18-I18-J18)*0.4 -> 0 | L18: =MAX(0,G18-H18-I18-J18-K18) -> 0 | M18: =F18 -> 4615.2206 | N18: =MAX(0,IF((J18+H18*Inputs!B43)<=23200,(J18+H18*Inputs!B43)*0.1,IF((J18+H18*Inputs!B43)<=94300,23200*0.1+((J18+H18*Inputs!B43)-23200)*0.12,IF((J18+H18*Inputs!B43)<=201050,23200*0.1+71100*0.12+((J18+H18*Inputs!B43)-94300)*0.22,23200*0.1+71100*0.12+106750*0.22+((J18+H18*Inputs!B43)-201050)*0.24)))) -> 27737 | O18: =J18*0.0637 -> 7338.2688 | P18: =H18+I18+J18+K18+L18-G18-N18-O18 -> 24353.025
A19: 81 | B19: =Inputs!B29*12*(1+Inputs!B20)^16 -> 134795.34 | C19: =IF(Inputs!B51=1,0,IF((VALUE(A19)-Inputs!B5)>=MAX(0,Inputs!B48-(Inputs!B5-Inputs!B4)),0,Inputs!B30*12)) -> 0 | D19: =Inputs!B31+Inputs!B32 -> 16500 | E19: =IF(76<65,Inputs!B35*12,0) -> 0 | F19: =Inputs!B33*12*(1+Inputs!B34)^16 -> 4845.9816 | G19: =B19+C19+D19+E19+F19 -> 156141.32 | H19: =IF(81>=Inputs!B25,IF(Inputs!B25=65,Inputs!B22*12,IF(Inputs!B25=70,Inputs!B24*12,Inputs!B23*12))*(1+Inputs!B21)^MAX(0,81-Inputs!B25),0) -> 67347.984 | I19: =IF(76>=Inputs!B26,Inputs!B23*12*0.5*(1+Inputs!B21)^MAX(0,76-Inputs!B26),0) -> 31269.649 | J19: ='Roth Conversion'!E19 -> 113804.21 | K19: =MAX(0,G19-H19-I19-J19)*0.4 -> 0 | L19: =MAX(0,G19-H19-I19-J19-K19) -> 0 | M19: =F19 -> 4845.9816 | N19: =MAX(0,IF((J19+H19*Inputs!B43)<=23200,(J19+H19*Inputs!B43)*0.1,IF((J19+H19*Inputs!B43)<=94300,23200*0.1+((J19+H19*Inputs!B43)-23200)*0.12,IF((J19+H19*Inputs!B43)<=201050,23200*0.1+71100*0.12+((J19+H19*Inputs!B43)-94300)*0.22,23200*0.1+71100*0.12+106750*0.22+((J19+H19*Inputs!B43)-201050)*0.24)))) -> 27737 | O19: =J19*0.0637 -> 7249.3284 | P19: =H19+I19+J19+K19+L19-G19-N19-O19 -> 21294.196
A20: 82 | B20: =Inputs!B29*12*(1+Inputs!B20)^17 -> 138839.2 | C20: =IF(Inputs!B51=1,0,IF((VALUE(A20)-Inputs!B5)>=MAX(0,Inputs!B48-(Inputs!B5-Inputs!B4)),0,Inputs!B30*12)) -> 0 | D20: =Inputs!B31+Inputs!B32 -> 16500 | E20: =IF(77<65,Inputs!B35*12,0) -> 0 | F20: =Inputs!B33*12*(1+Inputs!B34)^17 -> 5088.2807 | G20: =B20+C20+D20+E20+F20 -> 160427.48 | H20: =IF(82>=Inputs!B25,IF(Inputs!B25=65,Inputs!B22*12,IF(Inputs!B25=70,Inputs!B24*12,Inputs!B23*12))*(1+Inputs!B21)^MAX(0,82-Inputs!B25),0) -> 69031.684 | I20: =IF(77>=Inputs!B26,Inputs!B23*12*0.5*(1+Inputs!B21)^MAX(0,77-Inputs!B26),0) -> 32051.39 | J20: ='Roth Conversion'!E20 -> 112373.07 | K20: =MAX(0,G20-H20-I20-J20)*0.4 -> 0 | L20: =MAX(0,G20-H20-I20-J20-K20) -> 0 | M20: =F20 -> 5088.2807 | N20: =MAX(0,IF((J20+H20*Inputs!B43)<=23200,(J20+H20*Inputs!B43)*0.1,IF((J20+H20*Inputs!B43)<=94300,23200*0.1+((J20+H20*Inputs!B43)-23200)*0.12,IF((J20+H20*Inputs!B43)<=201050,23200*0.1+71100*0.12+((J20+H20*Inputs!B43)-94300)*0.22,23200*0.1+71100*0.12+106750*0.22+((J20+H20*Inputs!B43)-201050)*0.24)))) -> 27737 | O20: =J20*0.0637 -> 7158.1645 | P20: =H20+I20+J20+K20+L20-G20-N20-O20 -> 18133.497
A21: 83 | B21: =Inputs!B29*12*(1+Inputs!B20)^18 -> 143004.38 | C21: =IF(Inputs!B51=1,0,IF((VALUE(A21)-Inputs!B5)>=MAX(0,Inputs!B48-(Inputs!B5-Inputs!B4)),0,Inputs!B30*12)) -> 0 | D21: =Inputs!B31+Inputs!B32 -> 16500 | E21: =IF(78<65,Inputs!B35*12,0) -> 0 | F21: =Inputs!B33*12*(1+Inputs!B34)^18 -> 5342.6947 | G21: =B21+C21+D21+E21+F21 -> 164847.07 | H21: =IF(83>=Inputs!B25,IF(Inputs!B25=65,Inputs!B22*12,IF(Inputs!B25=70,Inputs!B24*12,Inputs!B23*12))*(1+Inputs!B21)^MAX(0,83-Inputs!B25),0) -> 70757.476 | I21: =IF(78>=Inputs!B26,Inputs!B23*12*0.5*(1+Inputs!B21)^MAX(0,78-Inputs!B26),0) -> 32852.675 | J21: ='Roth Conversion'!E21 -> 110906.15 | K21: =MAX(0,G21-H21-I21-J21)*0.4 -> 0 | L21: =MAX(0,G21-H21-I21-J21-K21) -> 0 | M21: =F21 -> 5342.6947 | N21: =MAX(0,IF((J21+H21*Inputs!B43)<=23200,(J21+H21*Inputs!B43)*0.1,IF((J21+H21*Inputs!B43)<=94300,23200*0.1+((J21+H21*Inputs!B43)-23200)*0.12,IF((J21+H21*Inputs!B43)<=201050,23200*0.1+71100*0.12+((J21+H21*Inputs!B43)-94300)*0.22,23200*0.1+71100*0.12+106750*0.22+((J21+H21*Inputs!B43)-201050)*0.24)))) -> 27737 | O21: =J21*0.0637 -> 7064.7215 | P21: =H21+I21+J21+K21+L21-G21-N21-O21 -> 14867.503
A22: 84 | B22: =Inputs!B29*12*(1+Inputs!B20)^19 -> 147294.51 | C22: =IF(Inputs!B51=1,0,IF((VALUE(A22)-Inputs!B5)>=MAX(0,Inputs!B48-(Inputs!B5-Inputs!B4)),0,Inputs!B30*12)) -> 0 | D22: =Inputs!B31+Inputs!B32 -> 16500 | E22: =IF(79<65,Inputs!B35*12,0) -> 0 | F22: =Inputs!B33*12*(1+Inputs!B34)^19 -> 5609.8294 | G22: =B22+C22+D22+E22+F22 -> 169404.34 | H22: =IF(84>=Inputs!B25,IF(Inputs!B25=65,Inputs!B22*12,IF(Inputs!B25=70,Inputs!B24*12,Inputs!B23*12))*(1+Inputs!B21)^MAX(0,84-Inputs!B25),0) -> 72526.413 | I22: =IF(79>=Inputs!B26,Inputs!B23*12*0.5*(1+Inputs!B21)^MAX(0,79-Inputs!B26),0) -> 33673.992 | J22: ='Roth Conversion'!E22 -> 109402.55 | K22: =MAX(0,G22-H22-I22-J22)*0.4 -> 0 | L22: =MAX(0,G22-H22-I22-J22-K22) -> 0 | M22: =F22 -> 5609.8294 | N22: =MAX(0,IF((J22+H22*Inputs!B43)<=23200,(J22+H22*Inputs!B43)*0.1,IF((J22+H22*Inputs!B43)<=94300,23200*0.1+((J22+H22*Inputs!B43)-23200)*0.12,IF((J22+H22*Inputs!B43)<=201050,23200*0.1+71100*0.12+((J22+H22*Inputs!B43)-94300)*0.22,23200*0.1+71100*0.12+106750*0.22+((J22+H22*Inputs!B43)-201050)*0.24)))) -> 27737 | O22: =J22*0.0637 -> 6968.9424 | P22: =H22+I22+J22+K22+L22-G22-N22-O22 -> 11492.674
A23: 85 | B23: =Inputs!B29*12*(1+Inputs!B20)^20 -> 151713.34 | C23: =IF(Inputs!B51=1,0,IF((VALUE(A23)-Inputs!B5)>=MAX(0,Inputs!B48-(Inputs!B5-Inputs!B4)),0,Inputs!B30*12)) -> 0 | D23: =Inputs!B31+Inputs!B32 -> 16500 | E23: =IF(80<65,Inputs!B35*12,0) -> 0 | F23: =Inputs!B33*12*(1+Inputs!B34)^20 -> 5890.3209 | G23: =B23+C23+D23+E23+F23 -> 174103.66 | H23: =IF(85>=Inputs!B25,IF(Inputs!B25=65,Inputs!B22*12,IF(Inputs!B25=70,Inputs!B24*12,Inputs!B23*12))*(1+Inputs!B21)^MAX(0,85-Inputs!B25),0) -> 74339.573 | I23: =IF(80>=Inputs!B26,Inputs!B23*12*0.5*(1+Inputs!B21)^MAX(0,80-Inputs!B26),0) -> 34515.842 | J23: ='Roth Conversion'!E23 -> 107861.36 | K23: =MAX(0,G23-H23-I23-J23)*0.4 -> 0 | L23: =MAX(0,G23-H23-I23-J23-K23) -> 0 | M23: =F23 -> 5890.3209 | N23: =MAX(0,IF((J23+H23*Inputs!B43)<=23200,(J23+H23*Inputs!B43)*0.1,IF((J23+H23*Inputs!B43)<=94300,23200*0.1+((J23+H23*Inputs!B43)-23200)*0.12,IF((J23+H23*Inputs!B43)<=201050,23200*0.1+71100*0.12+((J23+H23*Inputs!B43)-94300)*0.22,23200*0.1+71100*0.12+106750*0.22+((J23+H23*Inputs!B43)-201050)*0.24)))) -> 27737 | O23: =J23*0.0637 -> 6870.7688 | P23: =H23+I23+J23+K23+L23-G23-N23-O23 -> 8005.3444

Sheet RMD
A1: REQUIRED MINIMUM DISTRIBUTIONS (Ages 73–85) | L1: IRS Uniform Lifetime Table
A2: RMDs begin at age 73 (SECURE 2.0). RMD = Trad 401k balance ÷ IRS Uniform Lifetime Factor. Roth conversion is done first; any remaining capacity can add extra conversions above RMD. RMD is mandatory income — taxed as ordinary income.
A3: Age | B3: Trad 401k Jan 1 ($) | C3: IRS Factor | D3: RMD Required ($) | E3: Roth Conv Done ($) | F3: Extra Conv Possible ($) | G3: Total Trad Draw ($) | H3: Fed Tax on Draw ($) | I3: State Tax ($) | J3: Net After Tax ($)
A4: 73 | B4: ='Roth Conversion'!B11 -> 1890395.3 | C4: =VLOOKUP(A4,L$4:M$16,2,0) -> 26.5 | D4: =IFERROR(ROUND(B4/C4,0),0) -> 71336 | E4: ='Roth Conversion'!E11 -> 124065.72 | F4: =MAX(0,D4-E4) -> 0 | G4: =MAX(D4,E4) -> 124065.72 | H4: =MAX(0,IF((G4+'Withdrawal Plan'!H11*Inputs!B43)<=23200,(G4+'Withdrawal Plan'!H11*Inputs!B43)*0.1,IF((G4+'Withdrawal Plan'!H11*Inputs!B43)<=94300,23200*0.1+(G4+'Withdrawal Plan'!H11*Inputs!B43-23200)*0.12,IF((G4+'Withdrawal Plan'!H11*Inputs!B43)<=201050,23200*0.1+71100*0.12+(G4+'Withdrawal Plan'!H11*Inputs!B43-94300)*0.22,23200*0.1+71100*0.12+106750*0.22+(G4+'Withdrawal Plan'!H11*Inputs!B43-201050)*0.24)))) -> 27737 | I4: =ROUND(G4*0.0637,0) -> 7903 | J4: =G4-H4-I4 -> 88425.717 | L4: 73 | M4: 26.5
A5: 74 | B5: ='Roth Conversion'!B12 -> 1766329.6 | C5: =VLOOKUP(A5,L$4:M$16,2,0) -> 25.5 | D5: =IFERROR(ROUND(B5/C5,0),0) -> 69268 | E5: ='Roth Conversion'!E12 -> 122891.11 | F5: =MAX(0,D5-E5) -> 0 | G5: =MAX(D5,E5) -> 122891.11 | H5: =MAX(0,IF((G5+'Withdrawal Plan'!H12*Inputs!B43)<=23200,(G5+'Withdrawal Plan'!H12*Inputs!B43)*0.1,IF((G5+'Withdrawal Plan'!H12*Inputs!B43)<=94300,23200*0.1+(G5+'Withdrawal Plan'!H12*Inputs!B43-23200)*0.12,IF((G5+'Withdrawal Plan'!H12*Inputs!B43)<=201050,23200*0.1+71100*0.12+(G5+'Withdrawal Plan'!H12*Inputs!B43-94300)*0.22,23200*0.1+71100*0.12+106750*0.22+(G5+'Withdrawal Plan'!H12*Inputs!B43-201050)*0.24)))) -> 27737 | I5: =ROUND(G5*0.0637,0) -> 7828 | J5: =G5-H5-I5 -> 87326.11 | L5: 74 | M5: 25.5
A6: 75 | B6: ='Roth Conversion'!B13 -> 1643438.5 | C6: =VLOOKUP(A6,L$4:M$16,2,0) -> 24.6 | D6: =IFERROR(ROUND(B6/C6,0),0) -> 66806 | E6: ='Roth Conversion'!E13 -> 121687.14 | F6: =MAX(0,D6-E6) -> 0 | G6: =MAX(D6,E6) -> 121687.14 | H6: =MAX(0,IF((G6+'Withdrawal Plan'!H13*Inputs!B43)<=23200,(G6+'Withdrawal Plan'!H13*Inputs!B43)*0.1,IF((G6+'Withdrawal Plan'!H13*Inputs!B43)<=94300,23200*0.1+(G6+'Withdrawal Plan'!H13*Inputs!B43-23200)*0.12,IF((G6+'Withdrawal Plan'!H13*Inputs!B43)<=201050,23200*0.1+71100*0.12+(G6+'Withdrawal Plan'!H13*Inputs!B43-94300)*0.22,23200*0.1+71100*0.12+106750*0.22+(G6+'Withdrawal Plan'!H13*Inputs!B43-201050)*0.24)))) -> 27737 | I6: =ROUND(G6*0.0637,0) -> 7751 | J6: =G6-H6-I6 -> 86199.138 | L6: 75 | M6: 24.6
A7: 76 | B7: ='Roth Conversion'!B14 -> 1521751.4 | C7: =VLOOKUP(A7,L$4:M$16,2,0) -> 23.7 | D7: =IFERROR(ROUND(B7/C7,0),0) -> 64209 | E7: ='Roth Conversion'!E14 -> 120453.07 | F7: =MAX(0,D7-E7) -> 0 | G7: =MAX(D7,E7) -> 120453.07 | H7: =MAX(0,IF((G7+'Withdrawal Plan'!H14*Inputs!B43)<=23200,(G7+'Withdrawal Plan'!H14*Inputs!B43)*0.1,IF((G7+'Withdrawal Plan'!H14*Inputs!B43)<=94300,23200*0.1+(G7+'Withdrawal Plan'!H14*Inputs!B43-23200)*0.12,IF((G7+'Withdrawal Plan'!H14*Inputs!B43)<=201050,23200*0.1+71100*0.12+(G7+'Withdrawal Plan'!H14*Inputs!B43-94300)*0.22,23200*0.1+71100*0.12+106750*0.22+(G7+'Withdrawal Plan'!H14*Inputs!B43-201050)*0.24)))) -> 27737 | I7: =ROUND(G7*0.0637,0) -> 7673 | J7: =G7-H7-I7 -> 85043.066 | L7: 76 | M7: 23.7
A8: 77 | B8: ='Roth Conversion'!B15 -> 1401298.3 | C8: =VLOOKUP(A8,L$4:M$16,2,0) -> 22.9 | D8: =IFERROR(ROUND(B8/C8,0),0) -> 61192 | E8: ='Roth Conversion'!E15 -> 119188.14 | F8: =MAX(0,D8-E8) -> 0 | G8: =MAX(D8,E8) -> 119188.14 | H8: =MAX(0,IF((G8+'Withdrawal Plan'!H15*Inputs!B43)<=23200,(G8+'Withdrawal Plan'!H15*Inputs!B43)*0.1,IF((G8+'Withdrawal Plan'!H15*Inputs!B43)<=94300,23200*0.1+(G8+'Withdrawal Plan'!H15*Inputs!B43-23200)*0.12,IF((G8+'Withdrawal Plan'!H15*Inputs!B43)<=201050,23200*0.1+71100*0.12+(G8+'Withdrawal Plan'!H15*Inputs!B43-94300)*0.22,23200*0.1+71100*0.12+106750*0.22+(G8+'Withdrawal Plan'!H15*Inputs!B43-201050)*0.24)))) -> 27737 | I8: =ROUND(G8*0.0637,0) -> 7592 | J8: =G8-H8-I8 -> 83859.143 | L8: 77 | M8: 22.9
A9: 78 | B9: ='Roth Conversion'!B16 -> 1282110.1 | C9: =VLOOKUP(A9,L$4:M$16,2,0) -> 22 | D9: =IFERROR(ROUND(B9/C9,0),0) -> 58278 | E9: ='Roth Conversion'!E16 -> 117891.6 | F9: =MAX(0,D9-E9) -> 0 | G9: =MAX(D9,E9) -> 117891.6 | H9: =MAX(0,IF((G9+'Withdrawal Plan'!H16*Inputs!B43)<=23200,(G9+'Withdrawal Plan'!H16*Inputs!B43)*0.1,IF((G9+'Withdrawal Plan'!H16*Inputs!B43)<=94300,23200*0.1+(G9+'Withdrawal Plan'!H16*Inputs!B43-23200)*0.12,IF((G9+'Withdrawal Plan'!H16*Inputs!B43)<=201050,23200*0.1+71100*0.12+(G9+'Withdrawal Plan'!H16*Inputs!B43-94300)*0.22,23200*0.1+71100*0.12+106750*0.22+(G9+'Withdrawal Plan'!H16*Inputs!B43-201050)*0.24)))) -> 27737 | I9: =ROUND(G9*0.0637,0) -> 7510 | J9: =G9-H9-I9 -> 82644.596 | L9: 78 | M9: 22
A10: 79 | B10: ='Roth Conversion'!B17 -> 1164218.6 | C10: =VLOOKUP(A10,L$4:M$16,2,0) -> 21.1 | D10: =IFERROR(ROUND(B10/C10,0),0) -> 55176 | E10: ='Roth Conversion'!E17 -> 116562.64 | F10: =MAX(0,D10-E10) -> 0 | G10: =MAX(D10,E10) -> 116562.64 | H10: =MAX(0,IF((G10+'Withdrawal Plan'!H17*Inputs!B43)<=23200,(G10+'Withdrawal Plan'!H17*Inputs!B43)*0.1,IF((G10+'Withdrawal Plan'!H17*Inputs!B43)<=94300,23200*0.1+(G10+'Withdrawal Plan'!H17*Inputs!B43-23200)*0.12,IF((G10+'Withdrawal Plan'!H17*Inputs!B43)<=201050,23200*0.1+71100*0.12+(G10+'Withdrawal Plan'!H17*Inputs!B43-94300)*0.22,23200*0.1+71100*0.12+106750*0.22+(G10+'Withdrawal Plan'!H17*Inputs!B43-201050)*0.24)))) -> 27737 | I10: =ROUND(G10*0.0637,0) -> 7425 | J10: =G10-H10-I10 -> 81400.636 | L10: 79 | M10: 21.1
A11: 80 | B11: ='Roth Conversion'!B18 -> 1047655.9 | C11: =VLOOKUP(A11,L$4:M$16,2,0) -> 20.2 | D11: =IFERROR(ROUND(B11/C11,0),0) -> 51864 | E11: ='Roth Conversion'!E18 -> 115200.45 | F11: =MAX(0,D11-E11) -> 0 | G11: =MAX(D11,E11) -> 115200.45 | H11: =MAX(0,IF((G11+'Withdrawal Plan'!H18*Inputs!B43)<=23200,(G11+'Withdrawal Plan'!H18*Inputs!B43)*0.1,IF((G11+'Withdrawal Plan'!H18*Inputs!B43)<=94300,23200*0.1+(G11+'Withdrawal Plan'!H18*Inputs!B43-23200)*0.12,IF((G11+'Withdrawal Plan'!H18*Inputs!B43)<=201050,23200*0.1+71100*0.12+(G11+'Withdrawal Plan'!H18*Inputs!B43-94300)*0.22,23200*0.1+71100*0.12+106750*0.22+(G11+'Withdrawal Plan'!H18*Inputs!B43-201050)*0.24)))) -> 27737 | I11: =ROUND(G11*0.0637,0) -> 7338 | J11: =G11-H11-I11 -> 80125.452 | L11: 80 | M11: 20.2
A12: 81 | B12: ='Roth Conversion'!B19 -> 932455.46 | C12: =VLOOKUP(A12,L$4:M$16,2,0) -> 19.4 | D12: =IFERROR(ROUND(B12/C12,0),0) -> 48065 | E12: ='Roth Conversion'!E19 -> 113804.21 | F12: =MAX(0,D12-E12) -> 0 | G12: =MAX(D12,E12) -> 113804.21 | H12: =MAX(0,IF((G12+'Withdrawal Plan'!H19*Inputs!B43)<=23200,(G12+'Withdrawal Plan'!H19*Inputs!B43)*0.1,IF((G12+'Withdrawal Plan'!H19*Inputs!B43)<=94300,23200*0.1+(G12+'Withdrawal Plan'!H19*Inputs!B43-23200)*0.12,IF((G12+'Withdrawal Plan'!H19*Inputs!B43)<=201050,23200*0.1+71100*0.12+(G12+'Withdrawal Plan'!H19*Inputs!B43-94300)*0.22,23200*0.1+71100*0.12+106750*0.22+(G12+'Withdrawal Plan'!H19*Inputs!B43-201050)*0.24)))) -> 27737 | I12: =ROUND(G12*0.0637,0) -> 7249 | J12: =G12-H12-I12 -> 78818.213 | L12: 81 | M12: 19.4
A13: 82 | B13: ='Roth Conversion'!B20 -> 818651.25 | C13: =VLOOKUP(A13,L$4:M$16,2,0) -> 18.5 | D13: =IFERROR(ROUND(B13/C13,0),0) -> 44251 | E13: ='Roth Conversion'!E20 -> 112373.07 | F13: =MAX(0,D13-E13) -> 0 | G13: =MAX(D13,E13) -> 112373.07 | H13: =MAX(0,IF((G13+'Withdrawal Plan'!H20*Inputs!B43)<=23200,(G13+'Withdrawal Plan'!H20*Inputs!B43)*0.1,IF((G13+'Withdrawal Plan'!H20*Inputs!B43)<=94300,23200*0.1+(G13+'Withdrawal Plan'!H20*Inputs!B43-23200)*0.12,IF((G13+'Withdrawal Plan'!H20*Inputs!B43)<=201050,23200*0.1+71100*0.12+(G13+'Withdrawal Plan'!H20*Inputs!B43-94300)*0.22,23200*0.1+71100*0.12+106750*0.22+(G13+'Withdrawal Plan'!H20*Inputs!B43-201050)*0.24)))) -> 27737 | I13: =ROUND(G13*0.0637,0) -> 7158 | J13: =G13-H13-I13 -> 77478.069 | L13: 82 | M13: 18.5
A14: 83 | B14: ='Roth Conversion'!B21 -> 706278.18 | C14: =VLOOKUP(A14,L$4:M$16,2,0) -> 17.7 | D14: =IFERROR(ROUND(B14/C14,0),0) -> 39903 | E14: ='Roth Conversion'!E21 -> 110906.15 | F14: =MAX(0,D14-E14) -> 0 | G14: =MAX(D14,E14) -> 110906.15 | H14: =MAX(0,IF((G14+'Withdrawal Plan'!H21*Inputs!B43)<=23200,(G14+'Withdrawal Plan'!H21*Inputs!B43)*0.1,IF((G14+'Withdrawal Plan'!H21*Inputs!B43)<=94300,23200*0.1+(G14+'Withdrawal Plan'!H21*Inputs!B43-23200)*0.12,IF((G14+'Withdrawal Plan'!H21*Inputs!B43)<=201050,23200*0.1+71100*0.12+(G14+'Withdrawal Plan'!H21*Inputs!B43-94300)*0.22,23200*0.1+71100*0.12+106750*0.22+(G14+'Withdrawal Plan'!H21*Inputs!B43-201050)*0.24)))) -> 27737 | I14: =ROUND(G14*0.0637,0) -> 7065 | J14: =G14-H14-I14 -> 76104.145 | L14: 83 | M14: 17.7
A15: 84 | B15: ='Roth Conversion'!B22 -> 595372.04 | C15: =VLOOKUP(A15,L$4:M$16,2,0) -> 16.8 | D15: =IFERROR(ROUND(B15/C15,0),0) -> 35439 | E15: ='Roth Conversion'!E22 -> 109402.55 | F15: =MAX(0,D15-E15) -> 0 | G15: =MAX(D15,E15) -> 109402.55 | H15: =MAX(0,IF((G15+'Withdrawal Plan'!H22*Inputs!B43)<=23200,(G15+'Withdrawal Plan'!H22*Inputs!B43)*0.1,IF((G15+'Withdrawal Plan'!H22*Inputs!B43)<=94300,23200*0.1+(G15+'Withdrawal Plan'!H22*Inputs!B43-23200)*0.12,IF((G15+'Withdrawal Plan'!H22*Inputs!B43)<=201050,23200*0.1+71100*0.12+(G15+'Withdrawal Plan'!H22*Inputs!B43-94300)*0.22,23200*0.1+71100*0.12+106750*0.22+(G15+'Withdrawal Plan'!H22*Inputs!B43-201050)*0.24)))) -> 27737 | I15: =ROUND(G15*0.0637,0) -> 6969 | J15: =G15-H15-I15 -> 74696.549 | L15: 84 | M15: 16.8
A16: 85 | B16: ='Roth Conversion'!B23 -> 485969.49 | C16: =VLOOKUP(A16,L$4:M$16,2,0) -> 16 | D16: =IFERROR(ROUND(B16/C16,0),0) -> 30373 | E16: ='Roth Conversion'!E23 -> 107861.36 | F16: =MAX(0,D16-E16) -> 0 | G16: =MAX(D16,E16) -> 107861.36 | H16: =MAX(0,IF((G16+'Withdrawal Plan'!H23*Inputs!B43)<=23200,(G16+'Withdrawal Plan'!H23*Inputs!B43)*0.1,IF((G16+'Withdrawal Plan'!H23*Inputs!B43)<=94300,23200*0.1+(G16+'Withdrawal Plan'!H23*Inputs!B43-23200)*0.12,IF((G16+'Withdrawal Plan'!H23*Inputs!B43)<=201050,23200*0.1+71100*0.12+(G16+'Withdrawal Plan'!H23*Inputs!B43-94300)*0.22,23200*0.1+71100*0.12+106750*0.22+(G16+'Withdrawal Plan'!H23*Inputs!B43-201050)*0.24)))) -> 27737 | I16: =ROUND(G16*0.0637,0) -> 6871 | J16: =G16-H16-I16 -> 73253.363 | L16: 85 | M16: 16
A17: TOTALS | B17: =SUM(B4:B16) -> 15255924 | C17: =SUM(C4:C16) -> 274.9 | D17: =SUM(D4:D16) -> 696160 | E17: =SUM(E4:E16) -> 1512287.2 | F17: =SUM(F4:F16) -> 0 | G17: =SUM(G4:G16) -> 1512287.2 | H17: =SUM(H4:H16) -> 360581 | I17: =SUM(I4:I16) -> 96332 | J17: =SUM(J4:J16) -> 1055374.2

Sheet Tax Projection
A1: ANNUAL TAX PROJECTION (Ages 65–85)
A2: Full simulated tax return for each retirement year. Marginal rate = highest bracket reached. Effective rate = total fed tax ÷ total taxable income. IRMAA thresholds: Base ≤$206k, T1 ≤$258k, T2 ≤$322k, T3 ≤$386k, T4 ≤$750k, T5 >$750k (per person surcharge).
A3: Age | B3: Your SS ($) | C3: Wife SS ($) | D3: Roth Conv ($) | E3: SS Taxable ($) | F3: Gross Taxable ($) | G3: Std Ded ($) | H3: Net Taxable ($) | I3: Marginal Rate | J3: Fed Tax ($) | K3: Eff Rate | L3: IRMAA Tier | M3: NJ State Tax ($) | N3: Total Tax ($)
A4: 65 | B4: ='Withdrawal Plan'!H3 -> 0 | C4: ='Withdrawal Plan'!I3 -> 0 | D4: ='Roth Conversion'!E3 -> 171050 | E4: =(B4+C4)*Inputs!B43 -> 0 | F4: =D4+E4 -> 171050 | G4: =Inputs!B42 -> 30000 | H4: =MAX(0,F4-G4) -> 141050 | I4: =IF(H4<=23200,"10%",IF(H4<=94300,"12%",IF(H4<=201050,"22%",IF(H4<=383900,"24%","32%+")))) -> 22% | J4: =MAX(0,IF(H4<=23200,H4*0.1,IF(H4<=94300,23200*0.1+(H4-23200)*0.12,IF(H4<=201050,23200*0.1+71100*0.12+(H4-94300)*0.22,23200*0.1+71100*0.12+106750*0.22+(H4-201050)*0.24)))) -> 21137 | K4: =IFERROR(J4/MAX(1,H4),0) -> 0.14985466 | L4: =IF(F4<=206000,"Base $0",IF(F4<=258000,"T1 $594",IF(F4<=322000,"T2 $1,488",IF(F4<=386000,"T3 $2,382",IF(F4<=750000,"T4 $3,276","T5 $4,170"))))) -> Base $0 | M4: =ROUND(D4*0.0637,0) -> 10896 | N4: =J4+M4 -> 32033
A5: 66 | B5: ='Withdrawal Plan'!H4 -> 0 | C5: ='Withdrawal Plan'!I4 -> 0 | D5: ='Roth Conversion'!E4 -> 171050 | E5: =(B5+C5)*Inputs!B43 -> 0 | F5: =D5+E5 -> 171050 | G5: =Inputs!B42 -> 30000 | H5: =MAX(0,F5-G5) -> 141050 | I5: =IF(H5<=23200,"10%",IF(H5<=94300,"12%",IF(H5<=201050,"22%",IF(H5<=383900,"24%","32%+")))) -> 22% | J5: =MAX(0,IF(H5<=23200,H5*0.1,IF(H5<=94300,23200*0.1+(H5-23200)*0.12,IF(H5<=201050,23200*0.1+71100*0.12+(H5-94300)*0.22,23200*0.1+71100*0.12+106750*0.22+(H5-201050)*0.24)))) -> 21137 | K5: =IFERROR(J5/MAX(1,H5),0) -> 0.14985466 | L5: =IF(F5<=206000,"Base $0",IF(F5<=258000,"T1 $594",IF(F5<=322000,"T2 $1,488",IF(F5<=386000,"T3 $2,382",IF(F5<=750000,"T4 $3,276","T5 $4,170"))))) -> Base $0 | M5: =ROUND(D5*0.0637,0) -> 10896 | N5: =J5+M5 -> 32033
A6: 67 | B6: ='Withdrawal Plan'!H5 -> 47664 | C6: ='Withdrawal Plan'!I5 -> 0 | D6: ='Roth Conversion'!E5 -> 130535.6 | E6: =(B6+C6)*Inputs!B43 -> 40514.4 | F6: =D6+E6 -> 171050 | G6: =Inputs!B42 -> 30000 | H6: =MAX(0,F6-G6) -> 141050 | I6: =IF(H6<=23200,"10%",IF(H6<=94300,"12%",IF(H6<=201050,"22%",IF(H6<=383900,"24%","32%+")))) -> 22% | J6: =MAX(0,IF(H6<=23200,H6*0.1,IF(H6<=94300,23200*0.1+(H6-23200)*0.12,IF(H6<=201050,23200*0.1+71100*0.12+(H6-94300)*0.22,23200*0.1+71100*0.12+106750*0.22+(H6-201050)*0.24)))) -> 21137 | K6: =IFERROR(J6/MAX(1,H6),0) -> 0.14985466 | L6: =IF(F6<=206000,"Base $0",IF(F6<=258000,"T1 $594",IF(F6<=322000,"T2 $1,488",IF(F6<=386000,"T3 $2,382",IF(F6<=750000,"T4 $3,276","T5 $4,170"))))) -> Base $0 | M6: =ROUND(D6*0.0637,0) -> 8315 | N6: =J6+M6 -> 29452
A7: 68 | B7: ='Withdrawal Plan'!H6 -> 48855.6 | C7: ='Withdrawal Plan'!I6 -> 0 | D7: ='Roth Conversion'!E6 -> 129522.74 | E7: =(B7+C7)*Inputs!B43 -> 41527.26 | F7: =D7+E7 -> 171050 | G7: =Inputs!B42 -> 30000 | H7: =MAX(0,F7-G7) -> 141050 | I7: =IF(H7<=23200,"10%",IF(H7<=94300,"12%",IF(H7<=201050,"22%",IF(H7<=383900,"24%","32%+")))) -> 22% | J7: =MAX(0,IF(H7<=23200,H7*0.1,IF(H7<=94300,23200*0.1+(H7-23200)*0.12,IF(H7<=201050,23200*0.1+71100*0.12+(H7-94300)*0.22,23200*0.1+71100*0.12+106750*0.22+(H7-201050)*0.24)))) -> 21137 | K7: =IFERROR(J7/MAX(1,H7),0) -> 0.14985466 | L7: =IF(F7<=206000,"Base $0",IF(F7<=258000,"T1 $594",IF(F7<=322000,"T2 $1,488",IF(F7<=386000,"T3 $2,382",IF(F7<=750000,"T4 $3,276","T5 $4,170"))))) -> Base $0 | M7: =ROUND(D7*0.0637,0) -> 8251 | N7: =J7+M7 -> 29388
A8: 69 | B8: ='Withdrawal Plan'!H7 -> 50076.99 | C8: ='Withdrawal Plan'!I7 -> 0 | D8: ='Roth Conversion'!E7 -> 128484.56 | E8: =(B8+C8)*Inputs!B43 -> 42565.442 | F8: =D8+E8 -> 171050 | G8: =Inputs!B42 -> 30000 | H8: =MAX(0,F8-G8) -> 141050 | I8: =IF(H8<=23200,"10%",IF(H8<=94300,"12%",IF(H8<=201050,"22%",IF(H8<=383900,"24%","32%+")))) -> 22% | J8: =MAX(0,IF(H8<=23200,H8*0.1,IF(H8<=94300,23200*0.1+(H8-23200)*0.12,IF(H8<=201050,23200*0.1+71100*0.12+(H8-94300)*0.22,23200*0.1+71100*0.12+106750*0.22+(H8-201050)*0.24)))) -> 21137 | K8: =IFERROR(J8/MAX(1,H8),0) -> 0.14985466 | L8: =IF(F8<=206000,"Base $0",IF(F8<=258000,"T1 $594",IF(F8<=322000,"T2 $1,488",IF(F8<=386000,"T3 $2,382",IF(F8<=750000,"T4 $3,276","T5 $4,170"))))) -> Base $0 | M8: =ROUND(D8*0.0637,0) -> 8184 | N8: =J8+M8 -> 29321
